Workbook

Sheet PAINEL
A1: BIORENAL - PAINEL FINANCEIRO 2026
A2: Centro de Hemodiálise de Santa Inês - MA | dados da aba EXTRATO e RATEIOS
A4: SALDO EM CONTA | C4: TOTAL DE ENTRADAS | E4: TOTAL DE SAÍDAS
A5: =CADASTROS!$B$4+SUM(EXTRATO!$J$2:$J$3000)+SUM(EXTRATO!$M$2:$M$3000)-SUM(EXTRATO!$K$2:$K$3000)-SUM(EXTRATO!$L$2:$L$3000) -> 480714.13 | C5: =SUM(EXTRATO!$J$2:$J$3000) -> 5790013.3 | E5: =SUM(EXTRATO!$K$2:$K$3000) -> 5861088.3
A7: SALDO DA APLICAÇÃO(SEM RENDIMENTOS) | C7: VALOR RESGATADO NO ANO | E7: TOTAL DE DESPESAS CLASSIFICADAS
A8: =SUM(EXTRATO!$L$2:$L$3000)-SUM(EXTRATO!$M$850:M3000) -> 125496.54 | C8: =SUM(EXTRATO!$M$2:$M$3000) -> 1051789.1 | E8: =ANÁLISES!$N$19 -> 4881177.6
A11: SITUAÇÃO DO TRABALHO
A12: Movimentos bancários registrados | C12: =COUNT(EXTRATO!$C$2:$C$3000) -> 1061
A13: Movimentos com rateio OK | C13: =COUNTIF(EXTRATO!$Q$2:$Q$3000,"RATEIO OK") -> 895
A14: Movimentos NÃO classificados | C14: =COUNTIF(EXTRATO!$Q$2:$Q$3000,"NÃO CLASSIFICADO")+COUNTIF(EXTRATO!$Q$2:$Q$3000,"PENDENTE DE RATEIO") -> 165
A15: Movimentos com DIVERGÊNCIA de rateio | C15: =COUNTIF(EXTRATO!$Q$2:$Q$3000,"DIVERGÊNCIA") -> 1
A16: % classificado | C16: =IFERROR(C13/C12,0) -> 0.84354383
A17: Linhas de rateio marcadas SUGERIDO (conferir) | C17: =COUNTIF(RATEIOS!$J$2:$J$3142,"SUGERIDO") -> 170
A18: Linhas de rateio PENDENTES (preencher) | C18: =COUNTIF(RATEIOS!$J$2:$J$3142,"PENDENTE")+COUNTIF(RATEIOS!$J$2:$J$3142,"REVISAR") -> 303
A19: Conciliados com o extrato | C19: =COUNTIF(EXTRATO!$R$2:$R$3000,"Conciliado") -> 1028
A20: Valor ainda sem classificação | C20: =SUMPRODUCT((RATEIOS!$D$2:$D$3142="")*1,RATEIOS!$F$2:$F$3142) -> 2117734.8
A22: MAIOR CATEGORIA DE DESPESA (ano)
A23: Categoria | C23: =INDEX(ANÁLISES!$A$7:$A$17,MATCH(MAX(ANÁLISES!$N$7:$N$17),ANÁLISES!$N$7:$N$17,0)) -> DESPESAS COM MATERIAIS PARA HEMODIÁLISE E DEMAIS CUSTOS
A24: Valor | C24: =MAX(ANÁLISES!$N$7:$N$17) -> 1175950.7
A27: COMO USAR
A28: 1. EXTRATO: inclua cada movimento na próxima linha livre e preencha a DATA. O ID é automático; mantenha-o para preservar o vínculo.
A29: 2. RATEIOS: data, mês, valor, histórico, natureza e fornecedor aparecem automaticamente. Preencha CATEGORIA e SUBCATEGORIA.
A30: 3. Para dividir: copie a linha em RATEIOS e use Inserir células copiadas. Mantenha o mesmo ID e ajuste o VALOR de cada parte até fechar com o banco.
A31: 4. PRESTAÇÃO DE CONTAS - escolha o mês no topo. Os valores aparecem automaticamente.
A32: 5. ANÁLISES - visão por categoria, subcategoria, fornecedor e mês. Nada para digitar.
A33: 6. INTEGRIDADE - confira antes de fechar o mês. Tudo deve estar OK.
A34: Automação até BAN-02999 (2.999 movimentos). VALOR e DETALHE podem ser editados; não substitua uma linha automática reservada para outro ID.
A37: LEGENDA
C38: Célula que você preenche
C39: OK / conciliado
C40: Precisa da sua atenção (sugerido, pendente ou a verificar)
C41: Divergência — resolver antes de fechar o mês

Sheet EXTRATO
A1: ID_LANC | B1: ORDEM | C1: DATA | D1: MÊS | E1: TIPO DE PAGAMENTO | F1: TIPO DE MOVIMENTAÇÃO | G1: HISTÓRICO DO BANCO | H1: FORNECEDOR/FAVORECIDO | I1: DOCUMENTO | J1: ENTRADA | K1: SAÍDA | L1: APLICAÇÃO | M1: RESGATE | N1: SALDO ACUMULADO | O1: TOTAL RATEADO | P1: DIFERENÇA | Q1: STATUS DO RATEIO | R1: STATUS DA CONCILIAÇÃO | S1: OBSERVAÇÃO
A2: BAN-00001 | B2: 1 | C2: 46024 | D2: =IF(C2="","",MONTH(C2)) -> 1 | E2: OUTROS | F2: RESGATE | G2: RESGATE BB CDB DI | H2: BANCO DO BRASIL - CDB DI | J2: 0 | K2: 0 | L2: 0 | M2: 8500 | N2: =IF(AND(C2="",J2=0,K2=0,L2=0,M2=0),"",CADASTROS!$B$4+SUM($J$2:J2)+SUM($M$2:M2)-SUM($K$2:K2)-SUM($L$2:L2)) -> 8500 | O2: =IF(A2="","",SUMIF(RATEIOS!$A$2:$A$3142,$A2,RATEIOS!$F$2:$F$3142)) -> 8500 | P2: =IF(A2="","",(J2+K2+L2+M2)-O2) -> 0 | Q2: =IF(AND(J2=0,K2=0,L2=0,M2=0),"",IF(O2=0,"PENDENTE DE RATEIO",IF(ABS(P2)>0.005,"DIVERGÊNCIA",IF(COUNTIF(RATEIOS!$A$2:$A$3142,$A2)-COUNTIFS(RATEIOS!$A$2:$A$3142,$A2,RATEIOS!$D$2:$D$3142,"<>")>0,"NÃO CLASSIFICADO","RATEIO OK")))) -> RATEIO OK | R2: Conciliado
A3: BAN-00002 | B3: 2 | C3: 46024 | D3: =IF(C3="","",MONTH(C3)) -> 1 | E3: OUTROS | F3: RESGATE | G3: RESGATE BB CDB DI | H3: BANCO DO BRASIL - CDB DI | J3: 0 | K3: 0 | L3: 0 | M3: 5.27 | N3: =IF(AND(C3="",J3=0,K3=0,L3=0,M3=0),"",CADASTROS!$B$4+SUM($J$2:J3)+SUM($M$2:M3)-SUM($K$2:K3)-SUM($L$2:L3)) -> 8505.27 | O3: =IF(A3="","",SUMIF(RATEIOS!$A$2:$A$3142,$A3,RATEIOS!$F$2:$F$3142)) -> 5.27 | P3: =IF(A3="","",(J3+K3+L3+M3)-O3) -> 0 | Q3: =IF(AND(J3=0,K3=0,L3=0,M3=0),"",IF(O3=0,"PENDENTE DE RATEIO",IF(ABS(P3)>0.005,"DIVERGÊNCIA",IF(COUNTIF(RATEIOS!$A$2:$A$3142,$A3)-COUNTIFS(RATEIOS!$A$2:$A$3142,$A3,RATEIOS!$D$2:$D$3142,"<>")>0,"NÃO CLASSIFICADO","RATEIO OK")))) -> RATEIO OK | R3: Conciliado
A4: BAN-00003 | B4: 3 | C4: 46024 | D4: =IF(C4="","",MONTH(C4)) -> 1 | E4: TRANSFERÊNCIA | F4: SAÍDA | G4: ANA CLAUDIA A. VARÃO (NF - VARÃO E ALMEIDA - ESSENCIAL PHARMA) - REF. IODETO DE POTÁSSIO | H4: ANA CLAUDIA A. VARÃO | I4: 245 | J4: 0 | K4: 270 | L4: 0 | M4: 0 | N4: =IF(AND(C4="",J4=0,K4=0,L4=0,M4=0),"",CADASTROS!$B$4+SUM($J$2:J4)+SUM($M$2:M4)-SUM($K$2:K4)-SUM($L$2:L4)) -> 8235.27 | O4: =IF(A4="","",SUMIF(RATEIOS!$A$2:$A$3142,$A4,RATEIOS!$F$2:$F$3142)) -> 270 | P4: =IF(A4="","",(J4+K4+L4+M4)-O4) -> 0 | Q4: =IF(AND(J4=0,K4=0,L4=0,M4=0),"",IF(O4=0,"PENDENTE DE RATEIO",IF(ABS(P4)>0.005,"DIVERGÊNCIA",IF(COUNTIF(RATEIOS!$A$2:$A$3142,$A4)-COUNTIFS(RATEIOS!$A$2:$A$3142,$A4,RATEIOS!$D$2:$D$3142,"<>")>0,"NÃO CLASSIFICADO","RATEIO OK")))) -> RATEIO OK | R4: Conciliado
A5: BAN-00004 | B5: 4 | C5: 46024 | D5: =IF(C5="","",MONTH(C5)) -> 1 | E5: BOLETO | F5: SAÍDA | G5: ALLMED PRONEFRO (REF. LINHA ARTERIAL E LINHA VENOSA) 1/3 | H5: ALLMED PRONEFRO | I5: 86260 | J5: 0 | K5: 1300.83 | L5: 0 | M5: 0 | N5: =IF(AND(C5="",J5=0,K5=0,L5=0,M5=0),"",CADASTROS!$B$4+SUM($J$2:J5)+SUM($M$2:M5)-SUM($K$2:K5)-SUM($L$2:L5)) -> 6934.44 | O5: =IF(A5="","",SUMIF(RATEIOS!$A$2:$A$3142,$A5,RATEIOS!$F$2:$F$3142)) -> 1300.83 | P5: =IF(A5="","",(J5+K5+L5+M5)-O5) -> 0 | Q5: =IF(AND(J5=0,K5=0,L5=0,M5=0),"",IF(O5=0,"PENDENTE DE RATEIO",IF(ABS(P5)>0.005,"DIVERGÊNCIA",IF(COUNTIF(RATEIOS!$A$2:$A$3142,$A5)-COUNTIFS(RATEIOS!$A$2:$A$3142,$A5,RATEIOS!$D$2:$D$3142,"<>")>0,"NÃO CLASSIFICADO","RATEIO OK")))) -> RATEIO OK | R5: Conciliado
A6: BAN-00005 | B6: 5 | C6: 46024 | D6: =IF(C6="","",MONTH(C6)) -> 1 | E6: BOLETO | F6: SAÍDA | G6: ALLMED PRONEFRO (REF. LINHA ARTERIAL E LINHA VENOSA) 2/2 | H6: ALLMED PRONEFRO | I6: 85727 | J6: 0 | K6: 1952.72 | L6: 0 | M6: 0 | N6: =IF(AND(C6="",J6=0,K6=0,L6=0,M6=0),"",CADASTROS!$B$4+SUM($J$2:J6)+SUM($M$2:M6)-SUM($K$2:K6)-SUM($L$2:L6)) -> 4981.72 | O6: =IF(A6="","",SUMIF(RATEIOS!$A$2:$A$3142,$A6,RATEIOS!$F$2:$F$3142)) -> 1952.72 | P6: =IF(A6="","",(J6+K6+L6+M6)-O6) -> 0 | Q6: =IF(AND(J6=0,K6=0,L6=0,M6=0),"",IF(O6=0,"PENDENTE DE RATEIO",IF(ABS(P6)>0.005,"DIVERGÊNCIA",IF(COUNTIF(RATEIOS!$A$2:$A$3142,$A6)-COUNTIFS(RATEIOS!$A$2:$A$3142,$A6,RATEIOS!$D$2:$D$3142,"<>")>0,"NÃO CLASSIFICADO","RATEIO OK")))) -> RATEIO OK | R6: Conciliado
A7: BAN-00006 | B7: 6 | C7: 46024 | D7: =IF(C7="","",MONTH(C7)) -> 1 | E7: BOLETO | F7: SAÍDA | G7: OMNIELMASTER HEMOMED (REF. CATETER) 2/2 | H7: OMNIELMASTER HEMOMED | I7: 26229 | J7: 0 | K7: 720 | L7: 0 | M7: 0 | N7: =IF(AND(C7="",J7=0,K7=0,L7=0,M7=0),"",CADASTROS!$B$4+SUM($J$2:J7)+SUM($M$2:M7)-SUM($K$2:K7)-SUM($L$2:L7)) -> 4261.72 | O7: =IF(A7="","",SUMIF(RATEIOS!$A$2:$A$3142,$A7,RATEIOS!$F$2:$F$3142)) -> 720 | P7: =IF(A7="","",(J7+K7+L7+M7)-O7) -> 0 | Q7: =IF(AND(J7=0,K7=0,L7=0,M7=0),"",IF(O7=0,"PENDENTE DE RATEIO",IF(ABS(P7)>0.005,"DIVERGÊNCIA",IF(COUNTIF(RATEIOS!$A$2:$A$3142,$A7)-COUNTIFS(RATEIOS!$A$2:$A$3142,$A7,RATEIOS!$D$2:$D$3142,"<>")>0,"NÃO CLASSIFICADO","RATEIO OK")))) -> RATEIO OK | R7: Conciliado
A8: BAN-00007 | B8: 7 | C8: 46024 | D8: =IF(C8="","",MONTH(C8)) -> 1 | E8: BOLETO | F8: SAÍDA | G8: DIALISE COMÉRCIO (REF. ÁCIDO E ISOLADOR) 2/2 | H8: DIALISE COMERCIO | I8: 11363 | J8: 0 | K8: 1840 | L8: 0 | M8: 0 | N8: =IF(AND(C8="",J8=0,K8=0,L8=0,M8=0),"",CADASTROS!$B$4+SUM($J$2:J8)+SUM($M$2:M8)-SUM($K$2:K8)-SUM($L$2:L8)) -> 2421.72 | O8: =IF(A8="","",SUMIF(RATEIOS!$A$2:$A$3142,$A8,RATEIOS!$F$2:$F$3142)) -> 1840 | P8: =IF(A8="","",(J8+K8+L8+M8)-O8) -> 0 | Q8: =IF(AND(J8=0,K8=0,L8=0,M8=0),"",IF(O8=0,"PENDENTE DE RATEIO",IF(ABS(P8)>0.005,"DIVERGÊNCIA",IF(COUNTIF(RATEIOS!$A$2:$A$3142,$A8)-COUNTIFS(RATEIOS!$A$2:$A$3142,$A8,RATEIOS!$D$2:$D$3142,"<>")>0,"NÃO CLASSIFICADO","RATEIO OK")))) -> RATEIO OK | R8: Conciliado
A9: BAN-00008 | B9: 8 | C9: 46024 | D9: =IF(C9="","",MONTH(C9)) -> 1 | E9: BOLETO | F9: SAÍDA | G9: DIÁLISE COMÉRCIO (REF. ÁCIDO PERACETICO E ISOLADOR) 1/2 | H9: DIALISE COMERCIO | I9: 87 | J9: 0 | K9: 2535 | L9: 0 | M9: 0 | N9: =IF(AND(C9="",J9=0,K9=0,L9=0,M9=0),"",CADASTROS!$B$4+SUM($J$2:J9)+SUM($M$2:M9)-SUM($K$2:K9)-SUM($L$2:L9)) -> -113.28 | O9: =IF(A9="","",SUMIF(RATEIOS!$A$2:$A$3142,$A9,RATEIOS!$F$2:$F$3142)) -> 2535 | P9: =IF(A9="","",(J9+K9+L9+M9)-O9) -> 0 | Q9: =IF(AND(J9=0,K9=0,L9=0,M9=0),"",IF(O9=0,"PENDENTE DE RATEIO",IF(ABS(P9)>0.005,"DIVERGÊNCIA",IF(COUNTIF(RATEIOS!$A$2:$A$3142,$A9)-COUNTIFS(RATEIOS!$A$2:$A$3142,$A9,RATEIOS!$D$2:$D$3142,"<>")>0,"NÃO CLASSIFICADO","RATEIO OK")))) -> RATEIO OK | R9: Conciliado
A10: BAN-00009 | B10: 9 | C10: 46024 | D10: =IF(C10="","",MONTH(C10)) -> 1 | E10: OUTROS | F10: RESGATE | G10: BB RENDE FÁCIL | H10: BANCO DO BRASIL - CDB DI | J10: 0 | K10: 0 | L10: 0 | M10: 113.28 | N10: =IF(AND(C10="",J10=0,K10=0,L10=0,M10=0),"",CADASTROS!$B$4+SUM($J$2:J10)+SUM($M$2:M10)-SUM($K$2:K10)-SUM($L$2:L10)) -> 1.8189894e-12 | O10: =IF(A10="","",SUMIF(RATEIOS!$A$2:$A$3142,$A10,RATEIOS!$F$2:$F$3142)) -> 113.28 | P10: =IF(A10="","",(J10+K10+L10+M10)-O10) -> 0 | Q10: =IF(AND(J10=0,K10=0,L10=0,M10=0),"",IF(O10=0,"PENDENTE DE RATEIO",IF(ABS(P10)>0.005,"DIVERGÊNCIA",IF(COUNTIF(RATEIOS!$A$2:$A$3142,$A10)-COUNTIFS(RATEIOS!$A$2:$A$3142,$A10,RATEIOS!$D$2:$D$3142,"<>")>0,"NÃO CLASSIFICADO","RATEIO OK")))) -> RATEIO OK | R10: Conciliado
A11: BAN-00010 | B11: 10 | C11: 46027 | D11: =IF(C11="","",MONTH(C11)) -> 1 | E11: OUTROS | F11: RESGATE | G11: RESGATE BB CDB DI | H11: BANCO DO BRASIL - CDB DI | J11: 0 | K11: 0 | L11: 0 | M11: 2500 | N11: =IF(AND(C11="",J11=0,K11=0,L11=0,M11=0),"",CADASTROS!$B$4+SUM($J$2:J11)+SUM($M$2:M11)-SUM($K$2:K11)-SUM($L$2:L11)) -> 2500 | O11: =IF(A11="","",SUMIF(RATEIOS!$A$2:$A$3142,$A11,RATEIOS!$F$2:$F$3142)) -> 2500 | P11: =IF(A11="","",(J11+K11+L11+M11)-O11) -> 0 | Q11: =IF(AND(J11=0,K11=0,L11=0,M11=0),"",IF(O11=0,"PENDENTE DE RATEIO",IF(ABS(P11)>0.005,"DIVERGÊNCIA",IF(COUNTIF(RATEIOS!$A$2:$A$3142,$A11)-COUNTIFS(RATEIOS!$A$2:$A$3142,$A11,RATEIOS!$D$2:$D$3142,"<>")>0,"NÃO CLASSIFICADO","RATEIO OK")))) -> RATEIO OK | R11: Conciliado
A12: BAN-00011 | B12: 11 | C12: 46027 | D12: =IF(C12="","",MONTH(C12)) -> 1 | E12: OUTROS | F12: RESGATE | G12: RESGATE BB CDB DI | H12: BANCO DO BRASIL - CDB DI | J12: 0 | K12: 0 | L12: 0 | M12: 2.45 | N12: =IF(AND(C12="",J12=0,K12=0,L12=0,M12=0),"",CADASTROS!$B$4+SUM($J$2:J12)+SUM($M$2:M12)-SUM($K$2:K12)-SUM($L$2:L12)) -> 2502.45 | O12: =IF(A12="","",SUMIF(RATEIOS!$A$2:$A$3142,$A12,RATEIOS!$F$2:$F$3142)) -> 2.45 | P12: =IF(A12="","",(J12+K12+L12+M12)-O12) -> 0 | Q12: =IF(AND(J12=0,K12=0,L12=0,M12=0),"",IF(O12=0,"PENDENTE DE RATEIO",IF(ABS(P12)>0.005,"DIVERGÊNCIA",IF(COUNTIF(RATEIOS!$A$2:$A$3142,$A12)-COUNTIFS(RATEIOS!$A$2:$A$3142,$A12,RATEIOS!$D$2:$D$3142,"<>")>0,"NÃO CLASSIFICADO","RATEIO OK")))) -> RATEIO OK | R12: Conciliado
A13: BAN-00012 | B13: 12 | C13: 46027 | D13: =IF(C13="","",MONTH(C13)) -> 1 | E13: BOLETO | F13: SAÍDA | G13: BRANDÃO & BRANDÃO (REF. MATERIAL DE LIMPEZA) 1/1 | H13: BRANDÃO & BRANDÃO | I13: 106199 | J13: 0 | K13: 727 | L13: 0 | M13: 0 | N13: =IF(AND(C13="",J13=0,K13=0,L13=0,M13=0),"",CADASTROS!$B$4+SUM($J$2:J13)+SUM($M$2:M13)-SUM($K$2:K13)-SUM($L$2:L13)) -> 1775.45 | O13: =IF(A13="","",SUMIF(RATEIOS!$A$2:$A$3142,$A13,RATEIOS!$F$2:$F$3142)) -> 727 | P13: =IF(A13="","",(J13+K13+L13+M13)-O13) -> 0 | Q13: =IF(AND(J13=0,K13=0,L13=0,M13=0),"",IF(O13=0,"PENDENTE DE RATEIO",IF(ABS(P13)>0.005,"DIVERGÊNCIA",IF(COUNTIF(RATEIOS!$A$2:$A$3142,$A13)-COUNTIFS(RATEIOS!$A$2:$A$3142,$A13,RATEIOS!$D$2:$D$3142,"<>")>0,"NÃO CLASSIFICADO","RATEIO OK")))) -> RATEIO OK | R13: Conciliado
A14: BAN-00013 | B14: 13 | C14: 46027 | D14: =IF(C14="","",MONTH(C14)) -> 1 | E14: BOLETO | F14: SAÍDA | G14: CASSIANO & CASSINOS CONTABILIDADE | H14: CASSIANO & CASSINOS CONTABILIDADE | I14: 826 | J14: 0 | K14: 1518 | L14: 0 | M14: 0 | N14: =IF(AND(C14="",J14=0,K14=0,L14=0,M14=0),"",CADASTROS!$B$4+SUM($J$2:J14)+SUM($M$2:M14)-SUM($K$2:K14)-SUM($L$2:L14)) -> 257.45 | O14: =IF(A14="","",SUMIF(RATEIOS!$A$2:$A$3142,$A14,RATEIOS!$F$2:$F$3142)) -> 1518 | P14: =IF(A14="","",(J14+K14+L14+M14)-O14) -> 0 | Q14: =IF(AND(J14=0,K14=0,L14=0,M14=0),"",IF(O14=0,"PENDENTE DE RATEIO",IF(ABS(P14)>0.005,"DIVERGÊNCIA",IF(COUNTIF(RATEIOS!$A$2:$A$3142,$A14)-COUNTIFS(RATEIOS!$A$2:$A$3142,$A14,RATEIOS!$D$2:$D$3142,"<>")>0,"NÃO CLASSIFICADO","RATEIO OK")))) -> RATEIO OK | R14: Conciliado
A15: BAN-00014 | B15: 14 | C15: 46028 | D15: =IF(C15="","",MONTH(C15)) -> 1 | E15: PIX | F15: SAÍDA | G15: GAS SÃO JOSE (NF - J V L NOBRE) - GÁS PARA A COPA | H15: GAS SÃO JOSE | I15: 5321 | J15: 0 | K15: 115 | L15: 0 | M15: 0 | N15: =IF(AND(C15="",J15=0,K15=0,L15=0,M15=0),"",CADASTROS!$B$4+SUM($J$2:J15)+SUM($M$2:M15)-SUM($K$2:K15)-SUM($L$2:L15)) -> 142.45 | O15: =IF(A15="","",SUMIF(RATEIOS!$A$2:$A$3142,$A15,RATEIOS!$F$2:$F$3142)) -> 115 | P15: =IF(A15="","",(J15+K15+L15+M15)-O15) -> 0 | Q15: =IF(AND(J15=0,K15=0,L15=0,M15=0),"",IF(O15=0,"PENDENTE DE RATEIO",IF(ABS(P15)>0.005,"DIVERGÊNCIA",IF(COUNTIF(RATEIOS!$A$2:$A$3142,$A15)-COUNTIFS(RATEIOS!$A$2:$A$3142,$A15,RATEIOS!$D$2:$D$3142,"<>")>0,"NÃO CLASSIFICADO","RATEIO OK")))) -> RATEIO OK | R15: Conciliado
A16: BAN-00015 | B16: 15 | C16: 46028 | D16: =IF(C16="","",MONTH(C16)) -> 1 | E16: PIX | F16: SAÍDA | G16: MARKETPLACE (NF - L C BRASIL IMPORT) - REF. SUPORTE PARA JALECOS | H16: MARKETPLACE MERCADO LIVRE | I16: 191282 | J16: 0 | K16: 120.24 | L16: 0 | M16: 0 | N16: =IF(AND(C16="",J16=0,K16=0,L16=0,M16=0),"",CADASTROS!$B$4+SUM($J$2:J16)+SUM($M$2:M16)-SUM($K$2:K16)-SUM($L$2:L16)) -> 22.21 | O16: =IF(A16="","",SUMIF(RATEIOS!$A$2:$A$3142,$A16,RATEIOS!$F$2:$F$3142)) -> 120.24 | P16: =IF(A16="","",(J16+K16+L16+M16)-O16) -> 0 | Q16: =IF(AND(J16=0,K16=0,L16=0,M16=0),"",IF(O16=0,"PENDENTE DE RATEIO",IF(ABS(P16)>0.005,"DIVERGÊNCIA",IF(COUNTIF(RATEIOS!$A$2:$A$3142,$A16)-COUNTIFS(RATEIOS!$A$2:$A$3142,$A16,RATEIOS!$D$2:$D$3142,"<>")>0,"NÃO CLASSIFICADO","RATEIO OK")))) -> RATEIO OK | R16: Conciliado
A17: BAN-00016 | B17: 16 | C17: 46029 | D17: =IF(C17="","",MONTH(C17)) -> 1 | E17: TRANSFERÊNCIA | F17: ENTRADA | G17: MA FES ENFERMAGEM (REF. PISO SALARIAL ENFERMAGEM - COMP. DEZ/2025) | H17: MA FES ENFERMAGEM | J17: 30897.61 | K17: 0 | L17: 0 | M17: 0 | N17: =IF(AND(C17="",J17=0,K17=0,L17=0,M17=0),"",CADASTROS!$B$4+SUM($J$2:J17)+SUM($M$2:M17)-SUM($K$2:K17)-SUM($L$2:L17)) -> 30919.82 | O17: =IF(A17="","",SUMIF(RATEIOS!$A$2:$A$3142,$A17,RATEIOS!$F$2:$F$3142)) -> 30897.61 | P17: =IF(A17="","",(J17+K17+L17+M17)-O17) -> 0 | Q17: =IF(AND(J17=0,K17=0,L17=0,M17=0),"",IF(O17=0,"PENDENTE DE RATEIO",IF(ABS(P17)>0.005,"DIVERGÊNCIA",IF(COUNTIF(RATEIOS!$A$2:$A$3142,$A17)-COUNTIFS(RATEIOS!$A$2:$A$3142,$A17,RATEIOS!$D$2:$D$3142,"<>")>0,"NÃO CLASSIFICADO","RATEIO OK")))) -> RATEIO OK | R17: Conciliado
A18: BAN-00017 | B18: 17 | C18: 46029 | D18: =IF(C18="","",MONTH(C18)) -> 1 | E18: PIX | F18: SAÍDA | G18: CASSIANO & CASSINOS CONTABILIDADE (REF. CERTIFICAÇÃO DIGITAL - PJ) | H18: CASSIANO & CASSINOS CONTABILIDADE | I18: 822 | J18: 0 | K18: 220 | L18: 0 | M18: 0 | N18: =IF(AND(C18="",J18=0,K18=0,L18=0,M18=0),"",CADASTROS!$B$4+SUM($J$2:J18)+SUM($M$2:M18)-SUM($K$2:K18)-SUM($L$2:L18)) -> 30699.82 | O18: =IF(A18="","",SUMIF(RATEIOS!$A$2:$A$3142,$A18,RATEIOS!$F$2:$F$3142)) -> 220 | P18: =IF(A18="","",(J18+K18+L18+M18)-O18) -> 0 | Q18: =IF(AND(J18=0,K18=0,L18=0,M18=0),"",IF(O18=0,"PENDENTE DE RATEIO",IF(ABS(P18)>0.005,"DIVERGÊNCIA",IF(COUNTIF(RATEIOS!$A$2:$A$3142,$A18)-COUNTIFS(RATEIOS!$A$2:$A$3142,$A18,RATEIOS!$D$2:$D$3142,"<>")>0,"NÃO CLASSIFICADO","RATEIO OK")))) -> RATEIO OK | R18: Conciliado
A19: BAN-00018 | B19: 18 | C19: 46029 | D19: =IF(C19="","",MONTH(C19)) -> 1 | E19: BOLETO | F19: SAÍDA | G19: CRISTALIA PRODUTOS (REF. HEPARINAS) 1/3 | H19: CRISTALIA PRODUTOS | I19: 862145 | J19: 0 | K19: 10335.4 | L19: 0 | M19: 0 | N19: =IF(AND(C19="",J19=0,K19=0,L19=0,M19=0),"",CADASTROS!$B$4+SUM($J$2:J19)+SUM($M$2:M19)-SUM($K$2:K19)-SUM($L$2:L19)) -> 20364.42 | O19: =IF(A19="","",SUMIF(RATEIOS!$A$2:$A$3142,$A19,RATEIOS!$F$2:$F$3142)) -> 10335.4 | P19: =IF(A19="","",(J19+K19+L19+M19)-O19) -> 0 | Q19: =IF(AND(J19=0,K19=0,L19=0,M19=0),"",IF(O19=0,"PENDENTE DE RATEIO",IF(ABS(P19)>0.005,"DIVERGÊNCIA",IF(COUNTIF(RATEIOS!$A$2:$A$3142,$A19)-COUNTIFS(RATEIOS!$A$2:$A$3142,$A19,RATEIOS!$D$2:$D$3142,"<>")>0,"NÃO CLASSIFICADO","RATEIO OK")))) -> RATEIO OK | R19: Conciliado
A20: BAN-00019 | B20: 19 | C20: 46029 | D20: =IF(C20="","",MONTH(C20)) -> 1 | E20: PIX | F20: SAÍDA | G20: EQUATORIAL MARANHÃO (ENERGIA - CASA ALUGUEL) | H20: EQUATORIAL MARANHÃO | J20: 0 | K20: 27.78 | L20: 0 | M20: 0 | N20: =IF(AND(C20="",J20=0,K20=0,L20=0,M20=0),"",CADASTROS!$B$4+SUM($J$2:J20)+SUM($M$2:M20)-SUM($K$2:K20)-SUM($L$2:L20)) -> 20336.64 | O20: =IF(A20="","",SUMIF(RATEIOS!$A$2:$A$3142,$A20,RATEIOS!$F$2:$F$3142)) -> 27.78 | P20: =IF(A20="","",(J20+K20+L20+M20)-O20) -> 0 | Q20: =IF(AND(J20=0,K20=0,L20=0,M20=0),"",IF(O20=0,"PENDENTE DE RATEIO",IF(ABS(P20)>0.005,"DIVERGÊNCIA",IF(COUNTIF(RATEIOS!$A$2:$A$3142,$A20)-COUNTIFS(RATEIOS!$A$2:$A$3142,$A20,RATEIOS!$D$2:$D$3142,"<>")>0,"NÃO CLASSIFICADO","RATEIO OK")))) -> RATEIO OK | R20: Conciliado
A21: BAN-00020 | B21: 20 | C21: 46029 | D21: =IF(C21="","",MONTH(C21)) -> 1 | E21: PIX | F21: SAÍDA | G21: ANTONIO SANTOS L. FILHO (REF. ALUGUEL CASA DE APOIO) | H21: ANTONIO SANTOS L. FILHO | I21: SEM NF | J21: 0 | K21: 400 | L21: 0 | M21: 0 | N21: =IF(AND(C21="",J21=0,K21=0,L21=0,M21=0),"",CADASTROS!$B$4+SUM($J$2:J21)+SUM($M$2:M21)-SUM($K$2:K21)-SUM($L$2:L21)) -> 19936.64 | O21: =IF(A21="","",SUMIF(RATEIOS!$A$2:$A$3142,$A21,RATEIOS!$F$2:$F$3142)) -> 400 | P21: =IF(A21="","",(J21+K21+L21+M21)-O21) -> 0 | Q21: =IF(AND(J21=0,K21=0,L21=0,M21=0),"",IF(O21=0,"PENDENTE DE RATEIO",IF(ABS(P21)>0.005,"DIVERGÊNCIA",IF(COUNTIF(RATEIOS!$A$2:$A$3142,$A21)-COUNTIFS(RATEIOS!$A$2:$A$3142,$A21,RATEIOS!$D$2:$D$3142,"<>")>0,"NÃO CLASSIFICADO","RATEIO OK")))) -> RATEIO OK | R21: Conciliado
A22: BAN-00021 | B22: 21 | C22: 46030 | D22: =IF(C22="","",MONTH(C22)) -> 1 | E22: BOLETO | F22: SAÍDA | G22: ALECRIM INDUSTRIA E COMÉRCIO (REF. PAPEL TOALHA) 1/1 | H22: ALECRIM INDUSTRIA E COMÉRCIO | I22: 7657 | J22: 0 | K22: 561.2 | L22: 0 | M22: 0 | N22: =IF(AND(C22="",J22=0,K22=0,L22=0,M22=0),"",CADASTROS!$B$4+SUM($J$2:J22)+SUM($M$2:M22)-SUM($K$2:K22)-SUM($L$2:L22)) -> 19375.44 | O22: =IF(A22="","",SUMIF(RATEIOS!$A$2:$A$3142,$A22,RATEIOS!$F$2:$F$3142)) -> 561.2 | P22: =IF(A22="","",(J22+K22+L22+M22)-O22) -> 0 | Q22: =IF(AND(J22=0,K22=0,L22=0,M22=0),"",IF(O22=0,"PENDENTE DE RATEIO",IF(ABS(P22)>0.005,"DIVERGÊNCIA",IF(COUNTIF(RATEIOS!$A$2:$A$3142,$A22)-COUNTIFS(RATEIOS!$A$2:$A$3142,$A22,RATEIOS!$D$2:$D$3142,"<>")>0,"NÃO CLASSIFICADO","RATEIO OK")))) -> RATEIO OK | R22: Conciliado
A23: BAN-00022 | B23: 22 | C23: 46030 | D23: =IF(C23="","",MONTH(C23)) -> 1 | E23: BOLETO | F23: SAÍDA | G23: BANCO VOLKSWAGEN (NF - CAVEPEL - REF. PRESTAÇÃO CARRO) 5/48 | H23: BANCO VOLKSWAGEN | I23: 38758 | J23: 0 | K23: 1935.4 | L23: 0 | M23: 0 | N23: =IF(AND(C23="",J23=0,K23=0,L23=0,M23=0),"",CADASTROS!$B$4+SUM($J$2:J23)+SUM($M$2:M23)-SUM($K$2:K23)-SUM($L$2:L23)) -> 17440.04 | O23: =IF(A23="","",SUMIF(RATEIOS!$A$2:$A$3142,$A23,RATEIOS!$F$2:$F$3142)) -> 1935.4 | P23: =IF(A23="","",(J23+K23+L23+M23)-O23) -> 0 | Q23: =IF(AND(J23=0,K23=0,L23=0,M23=0),"",IF(O23=0,"PENDENTE DE RATEIO",IF(ABS(P23)>0.005,"DIVERGÊNCIA",IF(COUNTIF(RATEIOS!$A$2:$A$3142,$A23)-COUNTIFS(RATEIOS!$A$2:$A$3142,$A23,RATEIOS!$D$2:$D$3142,"<>")>0,"NÃO CLASSIFICADO","RATEIO OK")))) -> RATEIO OK | R23: Conciliado
A24: BAN-00023 | B24: 23 | C24: 46030 | D24: =IF(C24="","",MONTH(C24)) -> 1 | E24: DÉBITO AUTOMÁTICO | F24: SAÍDA | G24: TARIFA BANCÁRIA (SALÁRIO CRÉD. CONTA) | H24: TARIFA BANCÁRIA | J24: 0 | K24: 26.25 | L24: 0 | M24: 0 | N24: =IF(AND(C24="",J24=0,K24=0,L24=0,M24=0),"",CADASTROS!$B$4+SUM($J$2:J24)+SUM($M$2:M24)-SUM($K$2:K24)-SUM($L$2:L24)) -> 17413.79 | O24: =IF(A24="","",SUMIF(RATEIOS!$A$2:$A$3142,$A24,RATEIOS!$F$2:$F$3142)) -> 26.25 | P24: =IF(A24="","",(J24+K24+L24+M24)-O24) -> 0 | Q24: =IF(AND(J24=0,K24=0,L24=0,M24=0),"",IF(O24=0,"PENDENTE DE RATEIO",IF(ABS(P24)>0.005,"DIVERGÊNCIA",IF(COUNTIF(RATEIOS!$A$2:$A$3142,$A24)-COUNTIFS(RATEIOS!$A$2:$A$3142,$A24,RATEIOS!$D$2:$D$3142,"<>")>0,"NÃO CLASSIFICADO","RATEIO OK")))) -> RATEIO OK | R24: Conciliado
A25: BAN-00024 | B25: 24 | C25: 46030 | D25: =IF(C25="","",MONTH(C25)) -> 1 | E25: OUTROS | F25: RESGATE | G25: BB RENDE FÁCIL | H25: BANCO DO BRASIL - CDB DI | J25: 0 | K25: 0 | L25: 0 | M25: 241.68 | N25: =IF(AND(C25="",J25=0,K25=0,L25=0,M25=0),"",CADASTROS!$B$4+SUM($J$2:J25)+SUM($M$2:M25)-SUM($K$2:K25)-SUM($L$2:L25)) -> 17655.47 | O25: =IF(A25="","",SUMIF(RATEIOS!$A$2:$A$3142,$A25,RATEIOS!$F$2:$F$3142)) -> 241.68 | P25: =IF(A25="","",(J25+K25+L25+M25)-O25) -> 0 | Q25: =IF(AND(J25=0,K25=0,L25=0,M25=0),"",IF(O25=0,"PENDENTE DE RATEIO",IF(ABS(P25)>0.005,"DIVERGÊNCIA",IF(COUNTIF(RATEIOS!$A$2:$A$3142,$A25)-COUNTIFS(RATEIOS!$A$2:$A$3142,$A25,RATEIOS!$D$2:$D$3142,"<>")>0,"NÃO CLASSIFICADO","RATEIO OK")))) -> RATEIO OK | R25: Conciliado
A26: BAN-00025 | B26: 25 | C26: 46030 | D26: =IF(C26="","",MONTH(C26)) -> 1 | E26: OUTROS | F26: RESGATE | G26: RESGATE BB CDB DI | H26: BANCO DO BRASIL - CDB DI | J26: 0 | K26: 0 | L26: 0 | M26: 37500 | N26: =IF(AND(C26="",J26=0,K26=0,L26=0,M26=0),"",CADASTROS!$B$4+SUM($J$2:J26)+SUM($M$2:M26)-SUM($K$2:K26)-SUM($L$2:L26)) -> 55155.47 | O26: =IF(A26="","",SUMIF(RATEIOS!$A$2:$A$3142,$A26,RATEIOS!$F$2:$F$3142)) -> 37500 | P26: =IF(A26="","",(J26+K26+L26+M26)-O26) -> 0 | Q26: =IF(AND(J26=0,K26=0,L26=0,M26=0),"",IF(O26=0,"PENDENTE DE RATEIO",IF(ABS(P26)>0.005,"DIVERGÊNCIA",IF(COUNTIF(RATEIOS!$A$2:$A$3142,$A26)-COUNTIFS(RATEIOS!$A$2:$A$3142,$A26,RATEIOS!$D$2:$D$3142,"<>")>0,"NÃO CLASSIFICADO","RATEIO OK")))) -> RATEIO OK | R26: Conciliado
A27: BAN-00026 | B27: 26 | C27: 46030 | D27: =IF(C27="","",MONTH(C27)) -> 1 | E27: FOLHA DE PAGAMENTO | F27: SAÍDA | G27: FOLHA DE PAGAMENTO (REF. PAGAMENTO DE SALÁRIO - COMP. 12/2026) | H27: FOLHA DE PAGAMENTO | J27: 0 | K27: 55071.75 | L27: 0 | M27: 0 | N27: =IF(AND(C27="",J27=0,K27=0,L27=0,M27=0),"",CADASTROS!$B$4+SUM($J$2:J27)+SUM($M$2:M27)-SUM($K$2:K27)-SUM($L$2:L27)) -> 83.72 | O27: =IF(A27="","",SUMIF(RATEIOS!$A$2:$A$3142,$A27,RATEIOS!$F$2:$F$3142)) -> 55071.75 | P27: =IF(A27="","",(J27+K27+L27+M27)-O27) -> 0 | Q27: =IF(AND(J27=0,K27=0,L27=0,M27=0),"",IF(O27=0,"PENDENTE DE RATEIO",IF(ABS(P27)>0.005,"DIVERGÊNCIA",IF(COUNTIF(RATEIOS!$A$2:$A$3142,$A27)-COUNTIFS(RATEIOS!$A$2:$A$3142,$A27,RATEIOS!$D$2:$D$3142,"<>")>0,"NÃO CLASSIFICADO","RATEIO OK")))) -> RATEIO OK | R27: Conciliado
A28: BAN-00027 | B28: 27 | C28: 46031 | D28: =IF(C28="","",MONTH(C28)) -> 1 | E28: OUTROS | F28: RESGATE | G28: RESGATE BB CDB DI | H28: BANCO DO BRASIL - CDB DI | J28: 0 | K28: 0 | L28: 0 | M28: 69 | N28: =IF(AND(C28="",J28=0,K28=0,L28=0,M28=0),"",CADASTROS!$B$4+SUM($J$2:J28)+SUM($M$2:M28)-SUM($K$2:K28)-SUM($L$2:L28)) -> 152.72 | O28: =IF(A28="","",SUMIF(RATEIOS!$A$2:$A$3142,$A28,RATEIOS!$F$2:$F$3142)) -> 69 | P28: =IF(A28="","",(J28+K28+L28+M28)-O28) -> 0 | Q28: =IF(AND(J28=0,K28=0,L28=0,M28=0),"",IF(O28=0,"PENDENTE DE RATEIO",IF(ABS(P28)>0.005,"DIVERGÊNCIA",IF(COUNTIF(RATEIOS!$A$2:$A$3142,$A28)-COUNTIFS(RATEIOS!$A$2:$A$3142,$A28,RATEIOS!$D$2:$D$3142,"<>")>0,"NÃO CLASSIFICADO","RATEIO OK")))) -> RATEIO OK | R28: Conciliado
A29: BAN-00028 | B29: 28 | C29: 46031 | D29: =IF(C29="","",MONTH(C29)) -> 1 | E29: BOLETO | F29: SAÍDA | G29: EQUATORIAL MARANHÃO (REF. ENERGIA ELÉTRICA DA CLÍNICA) - REF. DEZ/25 | H29: EQUATORIAL MARANHÃO | J29: 0 | K29: 21581.32 | L29: 0 | M29: 0 | N29: =IF(AND(C29="",J29=0,K29=0,L29=0,M29=0),"",CADASTROS!$B$4+SUM($J$2:J29)+SUM($M$2:M29)-SUM($K$2:K29)-SUM($L$2:L29)) -> -21428.6 | O29: =IF(A29="","",SUMIF(RATEIOS!$A$2:$A$3142,$A29,RATEIOS!$F$2:$F$3142)) -> 21581.32 | P29: =IF(A29="","",(J29+K29+L29+M29)-O29) -> 0 | Q29: =IF(AND(J29=0,K29=0,L29=0,M29=0),"",IF(O29=0,"PENDENTE DE RATEIO",IF(ABS(P29)>0.005,"DIVERGÊNCIA",IF(COUNTIF(RATEIOS!$A$2:$A$3142,$A29)-COUNTIFS(RATEIOS!$A$2:$A$3142,$A29,RATEIOS!$D$2:$D$3142,"<>")>0,"NÃO CLASSIFICADO","RATEIO OK")))) -> RATEIO OK | R29: Conciliado
A30: BAN-00029 | B30: 29 | C30: 46031 | D30: =IF(C30="","",MONTH(C30)) -> 1 | E30: TRANSFERÊNCIA | F30: SAÍDA | G30: A C R DA SILVA E CIA (SUPERMERCADO CAMINO - REF. COMPRAS QUINZENAIS - 08/12 E 23/12 ) | H30: CAMINO | I30: NF 10175 / NF 10256 | J30: 0 | K30: 4031.09 | L30: 0 | M30: 0 | N30: =IF(AND(C30="",J30=0,K30=0,L30=0,M30=0),"",CADASTROS!$B$4+SUM($J$2:J30)+SUM($M$2:M30)-SUM($K$2:K30)-SUM($L$2:L30)) -> -25459.69 | O30: =IF(A30="","",SUMIF(RATEIOS!$A$2:$A$3142,$A30,RATEIOS!$F$2:$F$3142)) -> 4031.09 | P30: =IF(A30="","",(J30+K30+L30+M30)-O30) -> 0 | Q30: =IF(AND(J30=0,K30=0,L30=0,M30=0),"",IF(O30=0,"PENDENTE DE RATEIO",IF(ABS(P30)>0.005,"DIVERGÊNCIA",IF(COUNTIF(RATEIOS!$A$2:$A$3142,$A30)-COUNTIFS(RATEIOS!$A$2:$A$3142,$A30,RATEIOS!$D$2:$D$3142,"<>")>0,"NÃO CLASSIFICADO","RATEIO OK")))) -> RATEIO OK | R30: Conciliado | S30: NF 10175 - R$ 2.029,48 / NF 10256 - R$ 2.001,61
A31: BAN-00030 | B31: 30 | C31: 46031 | D31: =IF(C31="","",MONTH(C31)) -> 1 | E31: PIX | F31: SAÍDA | G31: J G MARQUES CONVENIENCIA (REF. ALMOÇO HELENAS BRISTRÔ - AFONSO E EMANUELLE) | H31: J G MARQUES CONVENIENCIA | I31: CUPOM FISCAL | J31: 0 | K31: 94.6 | L31: 0 | M31: 0 | N31: =IF(AND(C31="",J31=0,K31=0,L31=0,M31=0),"",CADASTROS!$B$4+SUM($J$2:J31)+SUM($M$2:M31)-SUM($K$2:K31)-SUM($L$2:L31)) -> -25554.29 | O31: =IF(A31="","",SUMIF(RATEIOS!$A$2:$A$3142,$A31,RATEIOS!$F$2:$F$3142)) -> 94.6 | P31: =IF(A31="","",(J31+K31+L31+M31)-O31) -> 0 | Q31: =IF(AND(J31=0,K31=0,L31=0,M31=0),"",IF(O31=0,"PENDENTE DE RATEIO",IF(ABS(P31)>0.005,"DIVERGÊNCIA",IF(COUNTIF(RATEIOS!$A$2:$A$3142,$A31)-COUNTIFS(RATEIOS!$A$2:$A$3142,$A31,RATEIOS!$D$2:$D$3142,"<>")>0,"NÃO CLASSIFICADO","RATEIO OK")))) -> RATEIO OK | R31: Conciliado
A32: BAN-00031 | B32: 31 | C32: 46031 | D32: =IF(C32="","",MONTH(C32)) -> 1 | E32: PIX | F32: SAÍDA | G32: MARKETPLACE (NF - LOJA KICAPACHO) - REF. COMPRA DE 03 TAPETES SINALIZADORES | H32: MARKETPLACE MERCADO LIVRE | I32: 7410 / 7411 / 7412 | J32: 0 | K32: 387.03 | L32: 0 | M32: 0 | N32: =IF(AND(C32="",J32=0,K32=0,L32=0,M32=0),"",CADASTROS!$B$4+SUM($J$2:J32)+SUM($M$2:M32)-SUM($K$2:K32)-SUM($L$2:L32)) -> -25941.32 | O32: =IF(A32="","",SUMIF(RATEIOS!$A$2:$A$3142,$A32,RATEIOS!$F$2:$F$3142)) -> 387.03 | P32: =IF(A32="","",(J32+K32+L32+M32)-O32) -> 0 | Q32: =IF(AND(J32=0,K32=0,L32=0,M32=0),"",IF(O32=0,"PENDENTE DE RATEIO",IF(ABS(P32)>0.005,"DIVERGÊNCIA",IF(COUNTIF(RATEIOS!$A$2:$A$3142,$A32)-COUNTIFS(RATEIOS!$A$2:$A$3142,$A32,RATEIOS!$D$2:$D$3142,"<>")>0,"NÃO CLASSIFICADO","RATEIO OK")))) -> RATEIO OK | R32: Conciliado
A33: BAN-00032 | B33: 32 | C33: 46031 | D33: =IF(C33="","",MONTH(C33)) -> 1 | E33: OUTROS | F33: RESGATE | G33: RESGATE BB CDB DI | H33: BANCO DO BRASIL - CDB DI | J33: 0 | K33: 0 | L33: 0 | M33: 26000 | N33: =IF(AND(C33="",J33=0,K33=0,L33=0,M33=0),"",CADASTROS!$B$4+SUM($J$2:J33)+SUM($M$2:M33)-SUM($K$2:K33)-SUM($L$2:L33)) -> 58.68 | O33: =IF(A33="","",SUMIF(RATEIOS!$A$2:$A$3142,$A33,RATEIOS!$F$2:$F$3142)) -> 26000 | P33: =IF(A33="","",(J33+K33+L33+M33)-O33) -> 0 | Q33: =IF(AND(J33=0,K33=0,L33=0,M33=0),"",IF(O33=0,"PENDENTE DE RATEIO",IF(ABS(P33)>0.005,"DIVERGÊNCIA",IF(COUNTIF(RATEIOS!$A$2:$A$3142,$A33)-COUNTIFS(RATEIOS!$A$2:$A$3142,$A33,RATEIOS!$D$2:$D$3142,"<>")>0,"NÃO CLASSIFICADO","RATEIO OK")))) -> RATEIO OK | R33: Conciliado
A34: BAN-00033 | B34: 33 | C34: 46034 | D34: =IF(C34="","",MONTH(C34)) -> 1 | E34: OUTROS | F34: RESGATE | G34: CDB/RDB | H34: BANCO DO BRASIL - CDB DI | J34: 0 | K34: 0 | L34: 0 | M34: 57.72 | N34: =IF(AND(C34="",J34=0,K34=0,L34=0,M34=0),"",CADASTROS!$B$4+SUM($J$2:J34)+SUM($M$2:M34)-SUM($K$2:K34)-SUM($L$2:L34)) -> 116.4 | O34: =IF(A34="","",SUMIF(RATEIOS!$A$2:$A$3142,$A34,RATEIOS!$F$2:$F$3142)) -> 57.72 | P34: =IF(A34="","",(J34+K34+L34+M34)-O34) -> 0 | Q34: =IF(AND(J34=0,K34=0,L34=0,M34=0),"",IF(O34=0,"PENDENTE DE RATEIO",IF(ABS(P34)>0.005,"DIVERGÊNCIA",IF(COUNTIF(RATEIOS!$A$2:$A$3142,$A34)-COUNTIFS(RATEIOS!$A$2:$A$3142,$A34,RATEIOS!$D$2:$D$3142,"<>")>0,"NÃO CLASSIFICADO","RATEIO OK")))) -> RATEIO OK | R34: Conciliado
A35: BAN-00034 | B35: 34 | C35: 46034 | D35: =IF(C35="","",MONTH(C35)) -> 1 | E35: PIX | F35: SAÍDA | G35: TIM S/A | H35: TIM S/A | J35: 0 | K35: 290.1 | L35: 0 | M35: 0 | N35: =IF(AND(C35="",J35=0,K35=0,L35=0,M35=0),"",CADASTROS!$B$4+SUM($J$2:J35)+SUM($M$2:M35)-SUM($K$2:K35)-SUM($L$2:L35)) -> -173.7 | O35: =IF(A35="","",SUMIF(RATEIOS!$A$2:$A$3142,$A35,RATEIOS!$F$2:$F$3142)) -> 290.1 | P35: =IF(A35="","",(J35+K35+L35+M35)-O35) -> 0 | Q35: =IF(AND(J35=0,K35=0,L35=0,M35=0),"",IF(O35=0,"PENDENTE DE RATEIO",IF(ABS(P35)>0.005,"DIVERGÊNCIA",IF(COUNTIF(RATEIOS!$A$2:$A$3142,$A35)-COUNTIFS(RATEIOS!$A$2:$A$3142,$A35,RATEIOS!$D$2:$D$3142,"<>")>0,"NÃO CLASSIFICADO","RATEIO OK")))) -> NÃO CLASSIFICADO | R35: Conciliado
A36: BAN-00035 | B36: 35 | C36: 46034 | D36: =IF(C36="","",MONTH(C36)) -> 1 | E36: PIX | F36: ENTRADA | G36: BRITO, TORRES & LOBO (REF. ESTORNO DO PAGAMENTO TIM S/A) | H36: BRITO, TORRES & LOBO | J36: 290.1 | K36: 0 | L36: 0 | M36: 0 | N36: =IF(AND(C36="",J36=0,K36=0,L36=0,M36=0),"",CADASTROS!$B$4+SUM($J$2:J36)+SUM($M$2:M36)-SUM($K$2:K36)-SUM($L$2:L36)) -> 116.4 | O36: =IF(A36="","",SUMIF(RATEIOS!$A$2:$A$3142,$A36,RATEIOS!$F$2:$F$3142)) -> 290.1 | P36: =IF(A36="","",(J36+K36+L36+M36)-O36) -> 0 | Q36: =IF(AND(J36=0,K36=0,L36=0,M36=0),"",IF(O36=0,"PENDENTE DE RATEIO",IF(ABS(P36)>0.005,"DIVERGÊNCIA",IF(COUNTIF(RATEIOS!$A$2:$A$3142,$A36)-COUNTIFS(RATEIOS!$A$2:$A$3142,$A36,RATEIOS!$D$2:$D$3142,"<>")>0,"NÃO CLASSIFICADO","RATEIO OK")))) -> NÃO CLASSIFICADO | R36: Conciliado
A37: BAN-00036 | B37: 36 | C37: 46034 | D37: =IF(C37="","",MONTH(C37)) -> 1 | E37: PIX | F37: SAÍDA | G37: FERCASTRO (REF. BOTAS, SILICONE E PARAFUSO) | H37: FERCASTRO | I37: 7496 | J37: 0 | K37: 188 | L37: 0 | M37: 0 | N37: =IF(AND(C37="",J37=0,K37=0,L37=0,M37=0),"",CADASTROS!$B$4+SUM($J$2:J37)+SUM($M$2:M37)-SUM($K$2:K37)-SUM($L$2:L37)) -> -71.6 | O37: =IF(A37="","",SUMIF(RATEIOS!$A$2:$A$3142,$A37,RATEIOS!$F$2:$F$3142)) -> 188 | P37: =IF(A37="","",(J37+K37+L37+M37)-O37) -> 0 | Q37: =IF(AND(J37=0,K37=0,L37=0,M37=0),"",IF(O37=0,"PENDENTE DE RATEIO",IF(ABS(P37)>0.005,"DIVERGÊNCIA",IF(COUNTIF(RATEIOS!$A$2:$A$3142,$A37)-COUNTIFS(RATEIOS!$A$2:$A$3142,$A37,RATEIOS!$D$2:$D$3142,"<>")>0,"NÃO CLASSIFICADO","RATEIO OK")))) -> RATEIO OK | R37: Conciliado
A38: BAN-00037 | B38: 37 | C38: 46034 | D38: =IF(C38="","",MONTH(C38)) -> 1 | E38: TRANSFERÊNCIA | F38: SAÍDA | G38: M E S XAVIER (REF. CARGA DE 02 OXIGÊNIOS MEDICINAL) | H38: M E S XAVIER | I38: 273 | J38: 0 | K38: 360 | L38: 0 | M38: 0 | N38: =IF(AND(C38="",J38=0,K38=0,L38=0,M38=0),"",CADASTROS!$B$4+SUM($J$2:J38)+SUM($M$2:M38)-SUM($K$2:K38)-SUM($L$2:L38)) -> -431.6 | O38: =IF(A38="","",SUMIF(RATEIOS!$A$2:$A$3142,$A38,RATEIOS!$F$2:$F$3142)) -> 360 | P38: =IF(A38="","",(J38+K38+L38+M38)-O38) -> 0 | Q38: =IF(AND(J38=0,K38=0,L38=0,M38=0),"",IF(O38=0,"PENDENTE DE RATEIO",IF(ABS(P38)>0.005,"DIVERGÊNCIA",IF(COUNTIF(RATEIOS!$A$2:$A$3142,$A38)-COUNTIFS(RATEIOS!$A$2:$A$3142,$A38,RATEIOS!$D$2:$D$3142,"<>")>0,"NÃO CLASSIFICADO","RATEIO OK")))) -> RATEIO OK | R38: Conciliado
A39: BAN-00038 | B39: 38 | C39: 46034 | D39: =IF(C39="","",MONTH(C39)) -> 1 | E39: BOLETO | F39: SAÍDA | G39: INDIFILTROS FILTROS (RE. FILTROS, CARCAÇA, CHAVES) 2/2 | H39: INDIFILTROS FILTROS | I39: 53977 | J39: 0 | K39: 1428.14 | L39: 0 | M39: 0 | N39: =IF(AND(C39="",J39=0,K39=0,L39=0,M39=0),"",CADASTROS!$B$4+SUM($J$2:J39)+SUM($M$2:M39)-SUM($K$2:K39)-SUM($L$2:L39)) -> -1859.74 | O39: =IF(A39="","",SUMIF(RATEIOS!$A$2:$A$3142,$A39,RATEIOS!$F$2:$F$3142)) -> 1428.14 | P39: =IF(A39="","",(J39+K39+L39+M39)-O39) -> 0 | Q39: =IF(AND(J39=0,K39=0,L39=0,M39=0),"",IF(O39=0,"PENDENTE DE RATEIO",IF(ABS(P39)>0.005,"DIVERGÊNCIA",IF(COUNTIF(RATEIOS!$A$2:$A$3142,$A39)-COUNTIFS(RATEIOS!$A$2:$A$3142,$A39,RATEIOS!$D$2:$D$3142,"<>")>0,"NÃO CLASSIFICADO","RATEIO OK")))) -> RATEIO OK | R39: Conciliado
A40: BAN-00039 | B40: 39 | C40: 46034 | D40: =IF(C40="","",MONTH(C40)) -> 1 | E40: DÉBITO AUTOMÁTICO | F40: SAÍDA | G40: TARIFA BANCÁRIA (PACOTE DE SERVIÇOS) | H40: TARIFA PACOTE DE SERVIÇOS | J40: 0 | K40: 263 | L40: 0 | M40: 0 | N40: =IF(AND(C40="",J40=0,K40=0,L40=0,M40=0),"",CADASTROS!$B$4+SUM($J$2:J40)+SUM($M$2:M40)-SUM($K$2:K40)-SUM($L$2:L40)) -> -2122.74 | O40: =IF(A40="","",SUMIF(RATEIOS!$A$2:$A$3142,$A40,RATEIOS!$F$2:$F$3142)) -> 263 | P40: =IF(A40="","",(J40+K40+L40+M40)-O40) -> 0 | Q40: =IF(AND(J40=0,K40=0,L40=0,M40=0),"",IF(O40=0,"PENDENTE DE RATEIO",IF(ABS(P40)>0.005,"DIVERGÊNCIA",IF(COUNTIF(RATEIOS!$A$2:$A$3142,$A40)-COUNTIFS(RATEIOS!$A$2:$A$3142,$A40,RATEIOS!$D$2:$D$3142,"<>")>0,"NÃO CLASSIFICADO","RATEIO OK")))) -> RATEIO OK | R40: Conciliado
...

Sheet RATEIOS
A1: ID_LANC | B1: DATA | C1: MÊS | D1: CATEGORIA | E1: SUBCATEGORIA | F1: VALOR | G1: DETALHE DO COMPONENTE | H1: NATUREZA | I1: FORNECEDOR | J1: ORIGEM DA CLASSIFICAÇÃO | K1: CONFERÊNCIA
A2: BAN-00001 | B2: =IF(A2="","",IF(INDEX(EXTRATO!$C$2:$C$3000,MATCH($A2,EXTRATO!$A$2:$A$3000,0))="","",INDEX(EXTRATO!$C$2:$C$3000,MATCH($A2,EXTRATO!$A$2:$A$3000,0)))) -> 46024 | C2: =IF(B2="","",MONTH(B2)) -> 1 | D2: ENTRADAS | E2: Resgate de Aplicações Financeiras (CDI BB) | F2: 8500 | G2: RESGATE BB CDB DI | H2: =IF(A2="","",IF(INDEX(EXTRATO!$F$2:$F$3000,MATCH($A2,EXTRATO!$A$2:$A$3000,0))="","",INDEX(EXTRATO!$F$2:$F$3000,MATCH($A2,EXTRATO!$A$2:$A$3000,0)))) -> RESGATE | I2: =IF(A2="","",IF(INDEX(EXTRATO!$H$2:$H$3000,MATCH($A2,EXTRATO!$A$2:$A$3000,0))="","",INDEX(EXTRATO!$H$2:$H$3000,MATCH($A2,EXTRATO!$A$2:$A$3000,0)))) -> BANCO DO BRASIL - CDB DI | J2: AUTOMÁTICO | K2: =IF(AND(A2="",D2="",E2="",F2=""),"",IF(D2="","SEM CATEGORIA",IF(E2="","SEM SUBCATEGORIA",IF(COUNTIFS(CADASTROS!$L$7:$L$93,D2,CADASTROS!$D$7:$D$93,E2)=0,"INCOMPATÍVEL","OK")))) -> OK
A3: BAN-00002 | B3: =IF(A3="","",IF(INDEX(EXTRATO!$C$2:$C$3000,MATCH($A3,EXTRATO!$A$2:$A$3000,0))="","",INDEX(EXTRATO!$C$2:$C$3000,MATCH($A3,EXTRATO!$A$2:$A$3000,0)))) -> 46024 | C3: =IF(B3="","",MONTH(B3)) -> 1 | D3: ENTRADAS | E3: Resgate de Aplicações Financeiras (CDI BB) | F3: 5.27 | G3: RESGATE BB CDB DI | H3: =IF(A3="","",IF(INDEX(EXTRATO!$F$2:$F$3000,MATCH($A3,EXTRATO!$A$2:$A$3000,0))="","",INDEX(EXTRATO!$F$2:$F$3000,MATCH($A3,EXTRATO!$A$2:$A$3000,0)))) -> RESGATE | I3: =IF(A3="","",IF(INDEX(EXTRATO!$H$2:$H$3000,MATCH($A3,EXTRATO!$A$2:$A$3000,0))="","",INDEX(EXTRATO!$H$2:$H$3000,MATCH($A3,EXTRATO!$A$2:$A$3000,0)))) -> BANCO DO BRASIL - CDB DI | J3: AUTOMÁTICO | K3: =IF(AND(A3="",D3="",E3="",F3=""),"",IF(D3="","SEM CATEGORIA",IF(E3="","SEM SUBCATEGORIA",IF(COUNTIFS(CADASTROS!$L$7:$L$93,D3,CADASTROS!$D$7:$D$93,E3)=0,"INCOMPATÍVEL","OK")))) -> OK
A4: BAN-00003 | B4: =IF(A4="","",IF(INDEX(EXTRATO!$C$2:$C$3000,MATCH($A4,EXTRATO!$A$2:$A$3000,0))="","",INDEX(EXTRATO!$C$2:$C$3000,MATCH($A4,EXTRATO!$A$2:$A$3000,0)))) -> 46024 | C4: =IF(B4="","",MONTH(B4)) -> 1 | D4: DESPESAS COM MATERIAIS PARA HEMODIÁLISE E DEMAIS CUSTOS | E4: Agulhas, Seringas, Máscaras, Luvas, Equipo e Med. Div. | F4: 270 | G4: ANA CLAUDIA A. VARÃO (NF - VARÃO E ALMEIDA - ESSENCIAL PHARMA) - REF. IODETO DE POTÁSSIO | H4: =IF(A4="","",IF(INDEX(EXTRATO!$F$2:$F$3000,MATCH($A4,EXTRATO!$A$2:$A$3000,0))="","",INDEX(EXTRATO!$F$2:$F$3000,MATCH($A4,EXTRATO!$A$2:$A$3000,0)))) -> SAÍDA | I4: =IF(A4="","",IF(INDEX(EXTRATO!$H$2:$H$3000,MATCH($A4,EXTRATO!$A$2:$A$3000,0))="","",INDEX(EXTRATO!$H$2:$H$3000,MATCH($A4,EXTRATO!$A$2:$A$3000,0)))) -> ANA CLAUDIA A. VARÃO | J4: MAPEADO | K4: =IF(AND(A4="",D4="",E4="",F4=""),"",IF(D4="","SEM CATEGORIA",IF(E4="","SEM SUBCATEGORIA",IF(COUNTIFS(CADASTROS!$L$7:$L$93,D4,CADASTROS!$D$7:$D$93,E4)=0,"INCOMPATÍVEL","OK")))) -> OK
A5: BAN-00004 | B5: =IF(A5="","",IF(INDEX(EXTRATO!$C$2:$C$3000,MATCH($A5,EXTRATO!$A$2:$A$3000,0))="","",INDEX(EXTRATO!$C$2:$C$3000,MATCH($A5,EXTRATO!$A$2:$A$3000,0)))) -> 46024 | C5: =IF(B5="","",MONTH(B5)) -> 1 | D5: DESPESAS COM MATERIAIS PARA HEMODIÁLISE E DEMAIS CUSTOS | E5: Linha Arterial e Venosa | F5: 1300.83 | G5: ALLMED PRONEFRO (REF. LINHA ARTERIAL E LINHA VENOSA) 1/3 | H5: =IF(A5="","",IF(INDEX(EXTRATO!$F$2:$F$3000,MATCH($A5,EXTRATO!$A$2:$A$3000,0))="","",INDEX(EXTRATO!$F$2:$F$3000,MATCH($A5,EXTRATO!$A$2:$A$3000,0)))) -> SAÍDA | I5: =IF(A5="","",IF(INDEX(EXTRATO!$H$2:$H$3000,MATCH($A5,EXTRATO!$A$2:$A$3000,0))="","",INDEX(EXTRATO!$H$2:$H$3000,MATCH($A5,EXTRATO!$A$2:$A$3000,0)))) -> ALLMED PRONEFRO | J5: MAPEADO | K5: =IF(AND(A5="",D5="",E5="",F5=""),"",IF(D5="","SEM CATEGORIA",IF(E5="","SEM SUBCATEGORIA",IF(COUNTIFS(CADASTROS!$L$7:$L$93,D5,CADASTROS!$D$7:$D$93,E5)=0,"INCOMPATÍVEL","OK")))) -> OK
A6: BAN-00005 | B6: =IF(A6="","",IF(INDEX(EXTRATO!$C$2:$C$3000,MATCH($A6,EXTRATO!$A$2:$A$3000,0))="","",INDEX(EXTRATO!$C$2:$C$3000,MATCH($A6,EXTRATO!$A$2:$A$3000,0)))) -> 46024 | C6: =IF(B6="","",MONTH(B6)) -> 1 | D6: DESPESAS COM MATERIAIS PARA HEMODIÁLISE E DEMAIS CUSTOS | E6: Linha Arterial e Venosa | F6: 1952.72 | G6: ALLMED PRONEFRO (REF. LINHA ARTERIAL E LINHA VENOSA) 2/2 | H6: =IF(A6="","",IF(INDEX(EXTRATO!$F$2:$F$3000,MATCH($A6,EXTRATO!$A$2:$A$3000,0))="","",INDEX(EXTRATO!$F$2:$F$3000,MATCH($A6,EXTRATO!$A$2:$A$3000,0)))) -> SAÍDA | I6: =IF(A6="","",IF(INDEX(EXTRATO!$H$2:$H$3000,MATCH($A6,EXTRATO!$A$2:$A$3000,0))="","",INDEX(EXTRATO!$H$2:$H$3000,MATCH($A6,EXTRATO!$A$2:$A$3000,0)))) -> ALLMED PRONEFRO | J6: MAPEADO | K6: =IF(AND(A6="",D6="",E6="",F6=""),"",IF(D6="","SEM CATEGORIA",IF(E6="","SEM SUBCATEGORIA",IF(COUNTIFS(CADASTROS!$L$7:$L$93,D6,CADASTROS!$D$7:$D$93,E6)=0,"INCOMPATÍVEL","OK")))) -> OK
A7: BAN-00006 | B7: =IF(A7="","",IF(INDEX(EXTRATO!$C$2:$C$3000,MATCH($A7,EXTRATO!$A$2:$A$3000,0))="","",INDEX(EXTRATO!$C$2:$C$3000,MATCH($A7,EXTRATO!$A$2:$A$3000,0)))) -> 46024 | C7: =IF(B7="","",MONTH(B7)) -> 1 | D7: DESPESAS COM MATERIAIS PARA HEMODIÁLISE E DEMAIS CUSTOS | E7: CDL e Perm-cath | F7: 720 | G7: OMNIELMASTER HEMOMED (REF. CATETER) 2/2 | H7: =IF(A7="","",IF(INDEX(EXTRATO!$F$2:$F$3000,MATCH($A7,EXTRATO!$A$2:$A$3000,0))="","",INDEX(EXTRATO!$F$2:$F$3000,MATCH($A7,EXTRATO!$A$2:$A$3000,0)))) -> SAÍDA | I7: =IF(A7="","",IF(INDEX(EXTRATO!$H$2:$H$3000,MATCH($A7,EXTRATO!$A$2:$A$3000,0))="","",INDEX(EXTRATO!$H$2:$H$3000,MATCH($A7,EXTRATO!$A$2:$A$3000,0)))) -> OMNIELMASTER HEMOMED | J7: MAPEADO | K7: =IF(AND(A7="",D7="",E7="",F7=""),"",IF(D7="","SEM CATEGORIA",IF(E7="","SEM SUBCATEGORIA",IF(COUNTIFS(CADASTROS!$L$7:$L$93,D7,CADASTROS!$D$7:$D$93,E7)=0,"INCOMPATÍVEL","OK")))) -> OK
A8: BAN-00007 | B8: =IF(A8="","",IF(INDEX(EXTRATO!$C$2:$C$3000,MATCH($A8,EXTRATO!$A$2:$A$3000,0))="","",INDEX(EXTRATO!$C$2:$C$3000,MATCH($A8,EXTRATO!$A$2:$A$3000,0)))) -> 46024 | C8: =IF(B8="","",MONTH(B8)) -> 1 | D8: DESPESAS COM MATERIAIS PARA HEMODIÁLISE E DEMAIS CUSTOS | E8: Peroxide | F8: 1350 | G8: DIALISE COMÉRCIO (REF. ÁCIDO PERACETICO 5%) 2/2 | H8: =IF(A8="","",IF(INDEX(EXTRATO!$F$2:$F$3000,MATCH($A8,EXTRATO!$A$2:$A$3000,0))="","",INDEX(EXTRATO!$F$2:$F$3000,MATCH($A8,EXTRATO!$A$2:$A$3000,0)))) -> SAÍDA | I8: =IF(A8="","",IF(INDEX(EXTRATO!$H$2:$H$3000,MATCH($A8,EXTRATO!$A$2:$A$3000,0))="","",INDEX(EXTRATO!$H$2:$H$3000,MATCH($A8,EXTRATO!$A$2:$A$3000,0)))) -> DIALISE COMERCIO | J8: MAPEADO | K8: =IF(AND(A8="",D8="",E8="",F8=""),"",IF(D8="","SEM CATEGORIA",IF(E8="","SEM SUBCATEGORIA",IF(COUNTIFS(CADASTROS!$L$7:$L$93,D8,CADASTROS!$D$7:$D$93,E8)=0,"INCOMPATÍVEL","OK")))) -> OK
A9: BAN-00007 | B9: =IF(A9="","",IF(INDEX(EXTRATO!$C$2:$C$3000,MATCH($A9,EXTRATO!$A$2:$A$3000,0))="","",INDEX(EXTRATO!$C$2:$C$3000,MATCH($A9,EXTRATO!$A$2:$A$3000,0)))) -> 46024 | C9: =IF(B9="","",MONTH(B9)) -> 1 | D9: DESPESAS COM MATERIAIS PARA HEMODIÁLISE E DEMAIS CUSTOS | E9: Agulhas, Seringas, Máscaras, Luvas, Equipo e Med. Div. | F9: 490 | G9: DIALISE COMÉRCIO (REF. ISOLADOR DE PRESSÃO) 2/2 | H9: =IF(A9="","",IF(INDEX(EXTRATO!$F$2:$F$3000,MATCH($A9,EXTRATO!$A$2:$A$3000,0))="","",INDEX(EXTRATO!$F$2:$F$3000,MATCH($A9,EXTRATO!$A$2:$A$3000,0)))) -> SAÍDA | I9: =IF(A9="","",IF(INDEX(EXTRATO!$H$2:$H$3000,MATCH($A9,EXTRATO!$A$2:$A$3000,0))="","",INDEX(EXTRATO!$H$2:$H$3000,MATCH($A9,EXTRATO!$A$2:$A$3000,0)))) -> DIALISE COMERCIO | J9: MAPEADO | K9: =IF(AND(A9="",D9="",E9="",F9=""),"",IF(D9="","SEM CATEGORIA",IF(E9="","SEM SUBCATEGORIA",IF(COUNTIFS(CADASTROS!$L$7:$L$93,D9,CADASTROS!$D$7:$D$93,E9)=0,"INCOMPATÍVEL","OK")))) -> OK
A10: BAN-00008 | B10: =IF(A10="","",IF(INDEX(EXTRATO!$C$2:$C$3000,MATCH($A10,EXTRATO!$A$2:$A$3000,0))="","",INDEX(EXTRATO!$C$2:$C$3000,MATCH($A10,EXTRATO!$A$2:$A$3000,0)))) -> 46024 | C10: =IF(B10="","",MONTH(B10)) -> 1 | D10: DESPESAS COM MATERIAIS PARA HEMODIÁLISE E DEMAIS CUSTOS | E10: Peroxide | F10: 1800 | G10: DIÁLISE COMÉRCIO (REF. ÁCIDO PERACETICO) 1/2 | H10: =IF(A10="","",IF(INDEX(EXTRATO!$F$2:$F$3000,MATCH($A10,EXTRATO!$A$2:$A$3000,0))="","",INDEX(EXTRATO!$F$2:$F$3000,MATCH($A10,EXTRATO!$A$2:$A$3000,0)))) -> SAÍDA | I10: =IF(A10="","",IF(INDEX(EXTRATO!$H$2:$H$3000,MATCH($A10,EXTRATO!$A$2:$A$3000,0))="","",INDEX(EXTRATO!$H$2:$H$3000,MATCH($A10,EXTRATO!$A$2:$A$3000,0)))) -> DIALISE COMERCIO | J10: MAPEADO | K10: =IF(AND(A10="",D10="",E10="",F10=""),"",IF(D10="","SEM CATEGORIA",IF(E10="","SEM SUBCATEGORIA",IF(COUNTIFS(CADASTROS!$L$7:$L$93,D10,CADASTROS!$D$7:$D$93,E10)=0,"INCOMPATÍVEL","OK")))) -> OK
A11: BAN-00008 | B11: =IF(A11="","",IF(INDEX(EXTRATO!$C$2:$C$3000,MATCH($A11,EXTRATO!$A$2:$A$3000,0))="","",INDEX(EXTRATO!$C$2:$C$3000,MATCH($A11,EXTRATO!$A$2:$A$3000,0)))) -> 46024 | C11: =IF(B11="","",MONTH(B11)) -> 1 | D11: DESPESAS COM MATERIAIS PARA HEMODIÁLISE E DEMAIS CUSTOS | E11: Agulhas, Seringas, Máscaras, Luvas, Equipo e Med. Div. | F11: 735 | G11: DIÁLISE COMÉRCIO (REF. ISOLADOR DE PRESSÃO) 1/2 | H11: =IF(A11="","",IF(INDEX(EXTRATO!$F$2:$F$3000,MATCH($A11,EXTRATO!$A$2:$A$3000,0))="","",INDEX(EXTRATO!$F$2:$F$3000,MATCH($A11,EXTRATO!$A$2:$A$3000,0)))) -> SAÍDA | I11: =IF(A11="","",IF(INDEX(EXTRATO!$H$2:$H$3000,MATCH($A11,EXTRATO!$A$2:$A$3000,0))="","",INDEX(EXTRATO!$H$2:$H$3000,MATCH($A11,EXTRATO!$A$2:$A$3000,0)))) -> DIALISE COMERCIO | J11: MAPEADO | K11: =IF(AND(A11="",D11="",E11="",F11=""),"",IF(D11="","SEM CATEGORIA",IF(E11="","SEM SUBCATEGORIA",IF(COUNTIFS(CADASTROS!$L$7:$L$93,D11,CADASTROS!$D$7:$D$93,E11)=0,"INCOMPATÍVEL","OK")))) -> OK
A12: BAN-00009 | B12: =IF(A12="","",IF(INDEX(EXTRATO!$C$2:$C$3000,MATCH($A12,EXTRATO!$A$2:$A$3000,0))="","",INDEX(EXTRATO!$C$2:$C$3000,MATCH($A12,EXTRATO!$A$2:$A$3000,0)))) -> 46024 | C12: =IF(B12="","",MONTH(B12)) -> 1 | D12: ENTRADAS | E12: Resgate de Aplicações Financeiras (CDI BB) | F12: 113.28 | G12: BB RENDE FÁCIL | H12: =IF(A12="","",IF(INDEX(EXTRATO!$F$2:$F$3000,MATCH($A12,EXTRATO!$A$2:$A$3000,0))="","",INDEX(EXTRATO!$F$2:$F$3000,MATCH($A12,EXTRATO!$A$2:$A$3000,0)))) -> RESGATE | I12: =IF(A12="","",IF(INDEX(EXTRATO!$H$2:$H$3000,MATCH($A12,EXTRATO!$A$2:$A$3000,0))="","",INDEX(EXTRATO!$H$2:$H$3000,MATCH($A12,EXTRATO!$A$2:$A$3000,0)))) -> BANCO DO BRASIL - CDB DI | J12: AUTOMÁTICO | K12: =IF(AND(A12="",D12="",E12="",F12=""),"",IF(D12="","SEM CATEGORIA",IF(E12="","SEM SUBCATEGORIA",IF(COUNTIFS(CADASTROS!$L$7:$L$93,D12,CADASTROS!$D$7:$D$93,E12)=0,"INCOMPATÍVEL","OK")))) -> OK
A13: BAN-00010 | B13: =IF(A13="","",IF(INDEX(EXTRATO!$C$2:$C$3000,MATCH($A13,EXTRATO!$A$2:$A$3000,0))="","",INDEX(EXTRATO!$C$2:$C$3000,MATCH($A13,EXTRATO!$A$2:$A$3000,0)))) -> 46027 | C13: =IF(B13="","",MONTH(B13)) -> 1 | D13: ENTRADAS | E13: Resgate de Aplicações Financeiras (CDI BB) | F13: 2500 | G13: RESGATE BB CDB DI | H13: =IF(A13="","",IF(INDEX(EXTRATO!$F$2:$F$3000,MATCH($A13,EXTRATO!$A$2:$A$3000,0))="","",INDEX(EXTRATO!$F$2:$F$3000,MATCH($A13,EXTRATO!$A$2:$A$3000,0)))) -> RESGATE | I13: =IF(A13="","",IF(INDEX(EXTRATO!$H$2:$H$3000,MATCH($A13,EXTRATO!$A$2:$A$3000,0))="","",INDEX(EXTRATO!$H$2:$H$3000,MATCH($A13,EXTRATO!$A$2:$A$3000,0)))) -> BANCO DO BRASIL - CDB DI | J13: AUTOMÁTICO | K13: =IF(AND(A13="",D13="",E13="",F13=""),"",IF(D13="","SEM CATEGORIA",IF(E13="","SEM SUBCATEGORIA",IF(COUNTIFS(CADASTROS!$L$7:$L$93,D13,CADASTROS!$D$7:$D$93,E13)=0,"INCOMPATÍVEL","OK")))) -> OK
... A36: BAN-00033 | B36: =IF(A36="","",IF(INDEX(EXTRATO!$C$2:$C$3000,MATCH($A36,EXTRATO!$A$2:$A$3000,0))="","",INDEX(EXTRATO!$C$2:$C$3000,MATCH($A36,EXTRATO!$A$2:$A$3000,0)))) -> 46034 | C36: =IF(B36="","",MONTH(B36)) -> 1 | D36: ENTRADAS | E36: Resgate de Aplicações Financeiras (CDI BB) | F36: 57.72 | G36: CDB/RDB | H36: =IF(A36="","",IF(INDEX(EXTRATO!$F$2:$F$3000,MATCH($A36,EXTRATO!$A$2:$A$3000,0))="","",INDEX(EXTRATO!$F$2:$F$3000,MATCH($A36,EXTRATO!$A$2:$A$3000,0)))) -> RESGATE | I36: =IF(A36="","",IF(INDEX(EXTRATO!$H$2:$H$3000,MATCH($A36,EXTRATO!$A$2:$A$3000,0))="","",INDEX(EXTRATO!$H$2:$H$3000,MATCH($A36,EXTRATO!$A$2:$A$3000,0)))) -> BANCO DO BRASIL - CDB DI | J36: AUTOMÁTICO | K36: =IF(AND(A36="",D36="",E36="",F36=""),"",IF(D36="","SEM CATEGORIA",IF(E36="","SEM SUBCATEGORIA",IF(COUNTIFS(CADASTROS!$L$7:$L$93,D36,CADASTROS!$D$7:$D$93,E36)=0,"INCOMPATÍVEL","OK")))) -> OK
A37: BAN-00034 | B37: =IF(A37="","",IF(INDEX(EXTRATO!$C$2:$C$3000,MATCH($A37,EXTRATO!$A$2:$A$3000,0))="","",INDEX(EXTRATO!$C$2:$C$3000,MATCH($A37,EXTRATO!$A$2:$A$3000,0)))) -> 46034 | C37: =IF(B37="","",MONTH(B37)) -> 1 | F37: 290.1 | G37: TIM S/A | H37: =IF(A37="","",IF(INDEX(EXTRATO!$F$2:$F$3000,MATCH($A37,EXTRATO!$A$2:$A$3000,0))="","",INDEX(EXTRATO!$F$2:$F$3000,MATCH($A37,EXTRATO!$A$2:$A$3000,0)))) -> SAÍDA | I37: =IF(A37="","",IF(INDEX(EXTRATO!$H$2:$H$3000,MATCH($A37,EXTRATO!$A$2:$A$3000,0))="","",INDEX(EXTRATO!$H$2:$H$3000,MATCH($A37,EXTRATO!$A$2:$A$3000,0)))) -> TIM S/A | J37: PENDENTE | K37: =IF(AND(A37="",D37="",E37="",F37=""),"",IF(D37="","SEM CATEGORIA",IF(E37="","SEM SUBCATEGORIA",IF(COUNTIFS(CADASTROS!$L$7:$L$93,D37,CADASTROS!$D$7:$D$93,E37)=0,"INCOMPATÍVEL","OK")))) -> SEM CATEGORIA
A38: BAN-00035 | B38: =IF(A38="","",IF(INDEX(EXTRATO!$C$2:$C$3000,MATCH($A38,EXTRATO!$A$2:$A$3000,0))="","",INDEX(EXTRATO!$C$2:$C$3000,MATCH($A38,EXTRATO!$A$2:$A$3000,0)))) -> 46034 | C38: =IF(B38="","",MONTH(B38)) -> 1 | F38: 290.1 | G38: BRITO, TORRES & LOBO (REF. ESTORNO DO PAGAMENTO TIM S/A) | H38: =IF(A38="","",IF(INDEX(EXTRATO!$F$2:$F$3000,MATCH($A38,EXTRATO!$A$2:$A$3000,0))="","",INDEX(EXTRATO!$F$2:$F$3000,MATCH($A38,EXTRATO!$A$2:$A$3000,0)))) -> ENTRADA | I38: =IF(A38="","",IF(INDEX(EXTRATO!$H$2:$H$3000,MATCH($A38,EXTRATO!$A$2:$A$3000,0))="","",INDEX(EXTRATO!$H$2:$H$3000,MATCH($A38,EXTRATO!$A$2:$A$3000,0)))) -> BRITO, TORRES & LOBO | J38: PENDENTE | K38: =IF(AND(A38="",D38="",E38="",F38=""),"",IF(D38="","SEM CATEGORIA",IF(E38="","SEM SUBCATEGORIA",IF(COUNTIFS(CADASTROS!$L$7:$L$93,D38,CADASTROS!$D$7:$D$93,E38)=0,"INCOMPATÍVEL","OK")))) -> SEM CATEGORIA
A39: BAN-00036 | B39: =IF(A39="","",IF(INDEX(EXTRATO!$C$2:$C$3000,MATCH($A39,EXTRATO!$A$2:$A$3000,0))="","",INDEX(EXTRATO!$C$2:$C$3000,MATCH($A39,EXTRATO!$A$2:$A$3000,0)))) -> 46034 | C39: =IF(B39="","",MONTH(B39)) -> 1 | D39: DESPESAS COM SALÁRIOS E BENEFÍCIOS | E39: EPIs e Fardamentos | F39: 169.77 | G39: FERCASTRO (REF. BOTAS PARA COLABORADORES) | H39: =IF(A39="","",IF(INDEX(EXTRATO!$F$2:$F$3000,MATCH($A39,EXTRATO!$A$2:$A$3000,0))="","",INDEX(EXTRATO!$F$2:$F$3000,MATCH($A39,EXTRATO!$A$2:$A$3000,0)))) -> SAÍDA | I39: =IF(A39="","",IF(INDEX(EXTRATO!$H$2:$H$3000,MATCH($A39,EXTRATO!$A$2:$A$3000,0))="","",INDEX(EXTRATO!$H$2:$H$3000,MATCH($A39,EXTRATO!$A$2:$A$3000,0)))) -> FERCASTRO | J39: MAPEADO | K39: =IF(AND(A39="",D39="",E39="",F39=""),"",IF(D39="","SEM CATEGORIA",IF(E39="","SEM SUBCATEGORIA",IF(COUNTIFS(CADASTROS!$L$7:$L$93,D39,CADASTROS!$D$7:$D$93,E39)=0,"INCOMPATÍVEL","OK")))) -> OK
A40: BAN-00036 | B40: =IF(A40="","",IF(INDEX(EXTRATO!$C$2:$C$3000,MATCH($A40,EXTRATO!$A$2:$A$3000,0))="","",INDEX(EXTRATO!$C$2:$C$3000,MATCH($A40,EXTRATO!$A$2:$A$3000,0)))) -> 46034 | C40: =IF(B40="","",MONTH(B40)) -> 1 | D40: MANUTENÇÃO E INFRAESTRUTURA | E40: Manutenção - Máquinas HD, Gerador, Osmose | F40: 18.23 | G40: FERCASTRO (REF. COLA DE SILICONE E PARAFUSOS) | H40: =IF(A40="","",IF(INDEX(EXTRATO!$F$2:$F$3000,MATCH($A40,EXTRATO!$A$2:$A$3000,0))="","",INDEX(EXTRATO!$F$2:$F$3000,MATCH($A40,EXTRATO!$A$2:$A$3000,0)))) -> SAÍDA | I40: =IF(A40="","",IF(INDEX(EXTRATO!$H$2:$H$3000,MATCH($A40,EXTRATO!$A$2:$A$3000,0))="","",INDEX(EXTRATO!$H$2:$H$3000,MATCH($A40,EXTRATO!$A$2:$A$3000,0)))) -> FERCASTRO | J40: MAPEADO | K40: =IF(AND(A40="",D40="",E40="",F40=""),"",IF(D40="","SEM CATEGORIA",IF(E40="","SEM SUBCATEGORIA",IF(COUNTIFS(CADASTROS!$L$7:$L$93,D40,CADASTROS!$D$7:$D$93,E40)=0,"INCOMPATÍVEL","OK")))) -> OK
A41: BAN-00037 | B41: =IF(A41="","",IF(INDEX(EXTRATO!$C$2:$C$3000,MATCH($A41,EXTRATO!$A$2:$A$3000,0))="","",INDEX(EXTRATO!$C$2:$C$3000,MATCH($A41,EXTRATO!$A$2:$A$3000,0)))) -> 46034 | C41: =IF(B41="","",MONTH(B41)) -> 1 | D41: DESPESAS COM MATERIAIS PARA HEMODIÁLISE E DEMAIS CUSTOS | E41: Oxigênio | F41: 360 | G41: M E S XAVIER (REF. CARGA DE 02 OXIGÊNIOS MEDICINAL) | H41: =IF(A41="","",IF(INDEX(EXTRATO!$F$2:$F$3000,MATCH($A41,EXTRATO!$A$2:$A$3000,0))="","",INDEX(EXTRATO!$F$2:$F$3000,MATCH($A41,EXTRATO!$A$2:$A$3000,0)))) -> SAÍDA | I41: =IF(A41="","",IF(INDEX(EXTRATO!$H$2:$H$3000,MATCH($A41,EXTRATO!$A$2:$A$3000,0))="","",INDEX(EXTRATO!$H$2:$H$3000,MATCH($A41,EXTRATO!$A$2:$A$3000,0)))) -> M E S XAVIER | J41: MAPEADO | K41: =IF(AND(A41="",D41="",E41="",F41=""),"",IF(D41="","SEM CATEGORIA",IF(E41="","SEM SUBCATEGORIA",IF(COUNTIFS(CADASTROS!$L$7:$L$93,D41,CADASTROS!$D$7:$D$93,E41)=0,"INCOMPATÍVEL","OK")))) -> OK
A42: BAN-00038 | B42: =IF(A42="","",IF(INDEX(EXTRATO!$C$2:$C$3000,MATCH($A42,EXTRATO!$A$2:$A$3000,0))="","",INDEX(EXTRATO!$C$2:$C$3000,MATCH($A42,EXTRATO!$A$2:$A$3000,0)))) -> 46034 | C42: =IF(B42="","",MONTH(B42)) -> 1 | D42: DESPESAS COM MATERIAIS PARA HEMODIÁLISE E DEMAIS CUSTOS | E42: Capilar, Filtros, Agulhas | F42: 1428.14 | G42: INDIFILTROS FILTROS (RE. FILTROS, CARCAÇA, CHAVES) 2/2 | H42: =IF(A42="","",IF(INDEX(EXTRATO!$F$2:$F$3000,MATCH($A42,EXTRATO!$A$2:$A$3000,0))="","",INDEX(EXTRATO!$F$2:$F$3000,MATCH($A42,EXTRATO!$A$2:$A$3000,0)))) -> SAÍDA | I42: =IF(A42="","",IF(INDEX(EXTRATO!$H$2:$H$3000,MATCH($A42,EXTRATO!$A$2:$A$3000,0))="","",INDEX(EXTRATO!$H$2:$H$3000,MATCH($A42,EXTRATO!$A$2:$A$3000,0)))) -> INDIFILTROS FILTROS | J42: MAPEADO | K42: =IF(AND(A42="",D42="",E42="",F42=""),"",IF(D42="","SEM CATEGORIA",IF(E42="","SEM SUBCATEGORIA",IF(COUNTIFS(CADASTROS!$L$7:$L$93,D42,CADASTROS!$D$7:$D$93,E42)=0,"INCOMPATÍVEL","OK")))) -> OK
A43: BAN-00039 | B43: =IF(A43="","",IF(INDEX(EXTRATO!$C$2:$C$3000,MATCH($A43,EXTRATO!$A$2:$A$3000,0))="","",INDEX(EXTRATO!$C$2:$C$3000,MATCH($A43,EXTRATO!$A$2:$A$3000,0)))) -> 46034 | C43: =IF(B43="","",MONTH(B43)) -> 1 | D43: DESPESAS ADMINISTRATIVAS | E43: Taxas e Tarifas | F43: 263 | G43: TARIFA PACOTE DE SERVIÇOS | H43: =IF(A43="","",IF(INDEX(EXTRATO!$F$2:$F$3000,MATCH($A43,EXTRATO!$A$2:$A$3000,0))="","",INDEX(EXTRATO!$F$2:$F$3000,MATCH($A43,EXTRATO!$A$2:$A$3000,0)))) -> SAÍDA | I43: =IF(A43="","",IF(INDEX(EXTRATO!$H$2:$H$3000,MATCH($A43,EXTRATO!$A$2:$A$3000,0))="","",INDEX(EXTRATO!$H$2:$H$3000,MATCH($A43,EXTRATO!$A$2:$A$3000,0)))) -> TARIFA PACOTE DE SERVIÇOS | J43: MAPEADO | K43: =IF(AND(A43="",D43="",E43="",F43=""),"",IF(D43="","SEM CATEGORIA",IF(E43="","SEM SUBCATEGORIA",IF(COUNTIFS(CADASTROS!$L$7:$L$93,D43,CADASTROS!$D$7:$D$93,E43)=0,"INCOMPATÍVEL","OK")))) -> OK
A44: BAN-00040 | B44: =IF(A44="","",IF(INDEX(EXTRATO!$C$2:$C$3000,MATCH($A44,EXTRATO!$A$2:$A$3000,0))="","",INDEX(EXTRATO!$C$2:$C$3000,MATCH($A44,EXTRATO!$A$2:$A$3000,0)))) -> 46034 | C44: =IF(B44="","",MONTH(B44)) -> 1 | D44: DESPESAS ADMINISTRATIVAS | E44: Suporte Informatica - Hardware, Internet, Sistemas e Câmeras | F44: 149.9 | G44: MARANET TELECOM (REF. INTERNET) | H44: =IF(A44="","",IF(INDEX(EXTRATO!$F$2:$F$3000,MATCH($A44,EXTRATO!$A$2:$A$3000,0))="","",INDEX(EXTRATO!$F$2:$F$3000,MATCH($A44,EXTRATO!$A$2:$A$3000,0)))) -> SAÍDA | I44: =IF(A44="","",IF(INDEX(EXTRATO!$H$2:$H$3000,MATCH($A44,EXTRATO!$A$2:$A$3000,0))="","",INDEX(EXTRATO!$H$2:$H$3000,MATCH($A44,EXTRATO!$A$2:$A$3000,0)))) -> MARANET TELECOM | J44: MAPEADO | K44: =IF(AND(A44="",D44="",E44="",F44=""),"",IF(D44="","SEM CATEGORIA",IF(E44="","SEM SUBCATEGORIA",IF(COUNTIFS(CADASTROS!$L$7:$L$93,D44,CADASTROS!$D$7:$D$93,E44)=0,"INCOMPATÍVEL","OK")))) -> OK
A45: BAN-00041 | B45: =IF(A45="","",IF(INDEX(EXTRATO!$C$2:$C$3000,MATCH($A45,EXTRATO!$A$2:$A$3000,0))="","",INDEX(EXTRATO!$C$2:$C$3000,MATCH($A45,EXTRATO!$A$2:$A$3000,0)))) -> 46034 | C45: =IF(B45="","",MONTH(B45)) -> 1 | D45: ENTRADAS | E45: Resgate de Aplicações Financeiras (CDI BB) | F45: 2500 | G45: RESGATE BB CDB DI | H45: =IF(A45="","",IF(INDEX(EXTRATO!$F$2:$F$3000,MATCH($A45,EXTRATO!$A$2:$A$3000,0))="","",INDEX(EXTRATO!$F$2:$F$3000,MATCH($A45,EXTRATO!$A$2:$A$3000,0)))) -> RESGATE | I45: =IF(A45="","",IF(INDEX(EXTRATO!$H$2:$H$3000,MATCH($A45,EXTRATO!$A$2:$A$3000,0))="","",INDEX(EXTRATO!$H$2:$H$3000,MATCH($A45,EXTRATO!$A$2:$A$3000,0)))) -> BANCO DO BRASIL - CDB DI | J45: AUTOMÁTICO | K45: =IF(AND(A45="",D45="",E45="",F45=""),"",IF(D45="","SEM CATEGORIA",IF(E45="","SEM SUBCATEGORIA",IF(COUNTIFS(CADASTROS!$L$7:$L$93,D45,CADASTROS!$D$7:$D$93,E45)=0,"INCOMPATÍVEL","OK")))) -> OK
A46: BAN-00042 | B46: =IF(A46="","",IF(INDEX(EXTRATO!$C$2:$C$3000,MATCH($A46,EXTRATO!$A$2:$A$3000,0))="","",INDEX(EXTRATO!$C$2:$C$3000,MATCH($A46,EXTRATO!$A$2:$A$3000,0)))) -> 46035 | C46: =IF(B46="","",MONTH(B46)) -> 1 | D46: ENTRADAS | E46: Resgate de Aplicações Financeiras (CDI BB) | F46: 7.2 | G46: RESGATE BB CDB DI | H46: =IF(A46="","",IF(INDEX(EXTRATO!$F$2:$F$3000,MATCH($A46,EXTRATO!$A$2:$A$3000,0))="","",INDEX(EXTRATO!$F$2:$F$3000,MATCH($A46,EXTRATO!$A$2:$A$3000,0)))) -> RESGATE | I46: =IF(A46="","",IF(INDEX(EXTRATO!$H$2:$H$3000,MATCH($A46,EXTRATO!$A$2:$A$3000,0))="","",INDEX(EXTRATO!$H$2:$H$3000,MATCH($A46,EXTRATO!$A$2:$A$3000,0)))) -> BANCO DO BRASIL - CDB DI | J46: AUTOMÁTICO | K46: =IF(AND(A46="",D46="",E46="",F46=""),"",IF(D46="","SEM CATEGORIA",IF(E46="","SEM SUBCATEGORIA",IF(COUNTIFS(CADASTROS!$L$7:$L$93,D46,CADASTROS!$D$7:$D$93,E46)=0,"INCOMPATÍVEL","OK")))) -> OK
A47: BAN-00043 | B47: =IF(A47="","",IF(INDEX(EXTRATO!$C$2:$C$3000,MATCH($A47,EXTRATO!$A$2:$A$3000,0))="","",INDEX(EXTRATO!$C$2:$C$3000,MATCH($A47,EXTRATO!$A$2:$A$3000,0)))) -> 46035 | C47: =IF(B47="","",MONTH(B47)) -> 1 | D47: DESPESAS COM SALÁRIOS E BENEFÍCIOS | E47: Folha de Pagamento (Repasse de piso da Enfermagem) | F47: 30897.61 | G47: FOLHA DE PAGAMENTO (REF. PISO SALARIAL DA ENFERMAGEM - COMP. DEZ/2025) | H47: =IF(A47="","",IF(INDEX(EXTRATO!$F$2:$F$3000,MATCH($A47,EXTRATO!$A$2:$A$3000,0))="","",INDEX(EXTRATO!$F$2:$F$3000,MATCH($A47,EXTRATO!$A$2:$A$3000,0)))) -> SAÍDA | I47: =IF(A47="","",IF(INDEX(EXTRATO!$H$2:$H$3000,MATCH($A47,EXTRATO!$A$2:$A$3000,0))="","",INDEX(EXTRATO!$H$2:$H$3000,MATCH($A47,EXTRATO!$A$2:$A$3000,0)))) -> FOLHA DE PAGAMENTO - PISO | J47: MAPEADO | K47: =IF(AND(A47="",D47="",E47="",F47=""),"",IF(D47="","SEM CATEGORIA",IF(E47="","SEM SUBCATEGORIA",IF(COUNTIFS(CADASTROS!$L$7:$L$93,D47,CADASTROS!$D$7:$D$93,E47)=0,"INCOMPATÍVEL","OK")))) -> OK
A48: BAN-00044 | B48: =IF(A48="","",IF(INDEX(EXTRATO!$C$2:$C$3000,MATCH($A48,EXTRATO!$A$2:$A$3000,0))="","",INDEX(EXTRATO!$C$2:$C$3000,MATCH($A48,EXTRATO!$A$2:$A$3000,0)))) -> 46035 | C48: =IF(B48="","",MONTH(B48)) -> 1 | D48: DESPESAS ADMINISTRATIVAS | E48: Taxas e Tarifas | F48: 31.5 | G48: TARIFA PAGAMENTO DE SALÁRIO | H48: =IF(A48="","",IF(INDEX(EXTRATO!$F$2:$F$3000,MATCH($A48,EXTRATO!$A$2:$A$3000,0))="","",INDEX(EXTRATO!$F$2:$F$3000,MATCH($A48,EXTRATO!$A$2:$A$3000,0)))) -> SAÍDA | I48: =IF(A48="","",IF(INDEX(EXTRATO!$H$2:$H$3000,MATCH($A48,EXTRATO!$A$2:$A$3000,0))="","",INDEX(EXTRATO!$H$2:$H$3000,MATCH($A48,EXTRATO!$A$2:$A$3000,0)))) -> TARIFA BANCÁRIA | J48: MAPEADO | K48: =IF(AND(A48="",D48="",E48="",F48=""),"",IF(D48="","SEM CATEGORIA",IF(E48="","SEM SUBCATEGORIA",IF(COUNTIFS(CADASTROS!$L$7:$L$93,D48,CADASTROS!$D$7:$D$93,E48)=0,"INCOMPATÍVEL","OK")))) -> OK
A49: BAN-00045 | B49: =IF(A49="","",IF(INDEX(EXTRATO!$C$2:$C$3000,MATCH($A49,EXTRATO!$A$2:$A$3000,0))="","",INDEX(EXTRATO!$C$2:$C$3000,MATCH($A49,EXTRATO!$A$2:$A$3000,0)))) -> 46035 | C49: =IF(B49="","",MONTH(B49)) -> 1 | D49: ENTRADAS | E49: Resgate de Aplicações Financeiras (CDI BB) | F49: 31000 | G49: RESGATE BB CDB DI | H49: =IF(A49="","",IF(INDEX(EXTRATO!$F$2:$F$3000,MATCH($A49,EXTRATO!$A$2:$A$3000,0))="","",INDEX(EXTRATO!$F$2:$F$3000,MATCH($A49,EXTRATO!$A$2:$A$3000,0)))) -> RESGATE | I49: =IF(A49="","",IF(INDEX(EXTRATO!$H$2:$H$3000,MATCH($A49,EXTRATO!$A$2:$A$3000,0))="","",INDEX(EXTRATO!$H$2:$H$3000,MATCH($A49,EXTRATO!$A$2:$A$3000,0)))) -> BANCO DO BRASIL - CDB DI | J49: AUTOMÁTICO | K49: =IF(AND(A49="",D49="",E49="",F49=""),"",IF(D49="","SEM CATEGORIA",IF(E49="","SEM SUBCATEGORIA",IF(COUNTIFS(CADASTROS!$L$7:$L$93,D49,CADASTROS!$D$7:$D$93,E49)=0,"INCOMPATÍVEL","OK")))) -> OK
A50: BAN-00046 | B50: =IF(A50="","",IF(INDEX(EXTRATO!$C$2:$C$3000,MATCH($A50,EXTRATO!$A$2:$A$3000,0))="","",INDEX(EXTRATO!$C$2:$C$3000,MATCH($A50,EXTRATO!$A$2:$A$3000,0)))) -> 46036 | C50: =IF(B50="","",MONTH(B50)) -> 1 | D50: ENTRADAS | E50: Resgate de Aplicações Financeiras (CDI BB) | F50: 102.3 | G50: RESGATE BB CDB DI | H50: =IF(A50="","",IF(INDEX(EXTRATO!$F$2:$F$3000,MATCH($A50,EXTRATO!$A$2:$A$3000,0))="","",INDEX(EXTRATO!$F$2:$F$3000,MATCH($A50,EXTRATO!$A$2:$A$3000,0)))) -> RESGATE | I50: =IF(A50="","",IF(INDEX(EXTRATO!$H$2:$H$3000,MATCH($A50,EXTRATO!$A$2:$A$3000,0))="","",INDEX(EXTRATO!$H$2:$H$3000,MATCH($A50,EXTRATO!$A$2:$A$3000,0)))) -> BANCO DO BRASIL - CDB DI | J50: AUTOMÁTICO | K50: =IF(AND(A50="",D50="",E50="",F50=""),"",IF(D50="","SEM CATEGORIA",IF(E50="","SEM SUBCATEGORIA",IF(COUNTIFS(CADASTROS!$L$7:$L$93,D50,CADASTROS!$D$7:$D$93,E50)=0,"INCOMPATÍVEL","OK")))) -> OK
... A312: BAN-00289 | B312: =IF(A312="","",IF(INDEX(EXTRATO!$C$2:$C$3000,MATCH($A312,EXTRATO!$A$2:$A$3000,0))="","",INDEX(EXTRATO!$C$2:$C$3000,MATCH($A312,EXTRATO!$A$2:$A$3000,0)))) -> 46097 | C312: =IF(B312="","",MONTH(B312)) -> 3 | D312: DESPESAS ADMINISTRATIVAS | E312: Taxas e Tarifas | F312: 35 | G312: TARIFA BANCÁRIA (SALÁRIO CRÉD. CONTA) | H312: =IF(A312="","",IF(INDEX(EXTRATO!$F$2:$F$3000,MATCH($A312,EXTRATO!$A$2:$A$3000,0))="","",INDEX(EXTRATO!$F$2:$F$3000,MATCH($A312,EXTRATO!$A$2:$A$3000,0)))) -> SAÍDA | I312: =IF(A312="","",IF(INDEX(EXTRATO!$H$2:$H$3000,MATCH($A312,EXTRATO!$A$2:$A$3000,0))="","",INDEX(EXTRATO!$H$2:$H$3000,MATCH($A312,EXTRATO!$A$2:$A$3000,0)))) -> TARIFA BANCÁRIA | J312: MAPEADO | K312: =IF(AND(A312="",D312="",E312="",F312=""),"",IF(D312="","SEM CATEGORIA",IF(E312="","SEM SUBCATEGORIA",IF(COUNTIFS(CADASTROS!$L$7:$L$93,D312,CADASTROS!$D$7:$D$93,E312)=0,"INCOMPATÍVEL","OK")))) -> OK
A313: BAN-00290 | B313: =IF(A313="","",IF(INDEX(EXTRATO!$C$2:$C$3000,MATCH($A313,EXTRATO!$A$2:$A$3000,0))="","",INDEX(EXTRATO!$C$2:$C$3000,MATCH($A313,EXTRATO!$A$2:$A$3000,0)))) -> 46098 | C313: =IF(B313="","",MONTH(B313)) -> 3 | D313: DESPESAS COM MATERIAIS PARA HEMODIÁLISE E DEMAIS CUSTOS | E313: Solução e Soro para HD | F313: =19012+31.04 -> 19043.04 | G313: FARMACE (REF. SOROS E SOLUÇÕES ) 1/2 | H313: =IF(A313="","",IF(INDEX(EXTRATO!$F$2:$F$3000,MATCH($A313,EXTRATO!$A$2:$A$3000,0))="","",INDEX(EXTRATO!$F$2:$F$3000,MATCH($A313,EXTRATO!$A$2:$A$3000,0)))) -> SAÍDA | I313: =IF(A313="","",IF(INDEX(EXTRATO!$H$2:$H$3000,MATCH($A313,EXTRATO!$A$2:$A$3000,0))="","",INDEX(EXTRATO!$H$2:$H$3000,MATCH($A313,EXTRATO!$A$2:$A$3000,0)))) -> FARMACE | J313: MAPEADO | K313: =IF(AND(A313="",D313="",E313="",F313=""),"",IF(D313="","SEM CATEGORIA",IF(E313="","SEM SUBCATEGORIA",IF(COUNTIFS(CADASTROS!$L$7:$L$93,D313,CADASTROS!$D$7:$D$93,E313)=0,"INCOMPATÍVEL","OK")))) -> OK
